Workbook

Sheet Employees
A1: Employee_ID | B1: Full_Name | C1: Gender | D1: Department | F1: Designation | G1: Company | H1: City | I1: Salary_Monthly | J1: Joining_Date | K1: Experience_Years | L1: Performance_Rating | M1: Employment_Status | N1: Manager_ID
A2: EMP0001 | B2: Priyanka Jena | C2: F | D2: DevOps | E2: =PROPER(D2) -> Devops | F2: SRE | G2: CoastalDev Studio | H2: Bhubaneswar | I2: 82466 | K2: 1.8 | L2: 4.5 | M2: Bikash Biswal
A3: EMP0002 | B3: Ranjit Samal | C3: female | D3: Design | E3: =PROPER(D3) -> Design | F3: UI Designer | G3: InfySoft Bhubaneswar | H3: Puri | I3: 56048 | J3: 05-03-2022 | K3: 2.8 | L3: 1.5 | M3: Resigned | N3: EMP0001
A4: EMP0003 | B4: Subhasree Dhal | C4: female | D4: DevOps | E4: =PROPER(D4) -> Devops | F4: SRE | G4: NilGiri Digitals | H4: Berhampur | I4: 196711 | J4: 07-03-2021 | K4: 3.8 | L4: 3.4 | M4: Active | N4: EMP0002
A5: EMP0004 | B5: Bikash Jena | C5: male | D5: Engineering | E5: =PROPER(D5) -> Engineering | F5: Tech Lead | G5: CoastalDev Studio | H5: Bhubaneswar | I5: 55130 | J5: 21-03-2021 | K5: 3.8 | L5: 2.7 | M5: On Leave | N5: EMP0002
A6: EMP0005 | B6: Bikash Nanda | C6: female | D6: Design | E6: =PROPER(D6) -> Design | F6: Design Lead | G6: SambalpurNet | H6: Cuttack | I6: 112039 | J6: 21-07-2023 | K6: 1.5 | L6: 4.9 | M6: Active | N6: EMP0003
A7: EMP0006 | B7: Tapas Sahu | C7: F | D7: Sales | E7: =PROPER(D7) -> Sales | F7: Account Manager | G7: BlueLotus IT | H7: Bhubaneswar | I7: 90908 | J7: 31-07-2022 | K7: 2.4 | L7: 2.9 | M7: Active | N7: EMP0002
A8: EMP0007 | B8: Jyotirmayee Ratha | C8: Female | D8: DevOps | E8: =PROPER(D8) -> Devops | F8: SRE | G8: SambalpurNet | H8: Rourkela | I8: 146760 | J8: 28-12-2018 | K8: 6 | M8: Active | N8: EMP0002
A9: EMP0008 | B9: Tanmay Nanda | C9: Male | D9: Product | E9: =PROPER(D9) -> Product | F9: Associate PM | G9: TributeAI | H9: Bhubaneswar | I9: 163509 | J9: 2023-01-31 | K9: 1.9 | L9: 2.3 | M9: Active | N9: EMP0004
A10: EMP0009 | B10: Bikash Routray | C10: male | D10: Sales | E10: =PROPER(D10) -> Sales | F10: Business Developer | G10: OdishaCode Labs | H10: Puri | I10: 27340 | J10: 14-11-2018 | K10: 6.1 | L10: 3.2 | M10: Active | N10: EMP0003
A11: EMP0010 | B11: Sudhansu Dhal | C11: Female | D11: Design | E11: =PROPER(D11) -> Design | F11: UX Researcher | G11: KalingaTech Pvt Ltd | H11: Bhubaneswar | I11: 48871 | J11: 21-02-2022 | K11: 2.9 | M11: On Leave | N11: EMP0005
A12: EMP0011 | B12: Lipsa Prusty | C12: female | D12: Engineering | E12: =PROPER(D12) -> Engineering | F12: Software Engineer | G12: NilGiri Digitals | H12: Bhubaneswar | I12: 181618 | J12: 22-03-2020 | K12: 4.8 | L12: 4.7 | M12: Active | N12: EMP0009
A13: EMP0012 | B13: Puspita Mahapatra | C13: M | D13: HR | E13: =PROPER(D13) -> Hr | F13: Talent Acquisition | G13: TributeAI | H13: Bhubaneswar | I13: 215352 | J13: 03-09-2023 | K13: 1.3 | L13: 2.6 | M13: Active | N13: EMP0007
A14: EMP0013 | B14: Nirmal Samal | C14: Male | D14: Data Science | E14: =PROPER(D14) -> Data Science | F14: Data Analyst | G14: NilGiri Digitals | H14: Puri | I14: 60493 | J14: 01-08-2022 | K14: 2.4 | L14: 4.6 | M14: On Leave | N14: EMP0006
A15: EMP0014 | B15: Chinmaya Ratha | C15: Female | D15: Design | E15: =PROPER(D15) -> Design | F15: Visual Designer | G15: NilGiri Digitals | H15: Berhampur | I15: 114298 | J15: 26-01-2020 | K15: 4.9 | L15: 3.5 | M15: Active | N15: EMP0004
A16: EMP0015 | B16: Tanmay Jena | C16: Female | D16: DevOps | E16: =PROPER(D16) -> Devops | F16: Cloud Architect | G16: SambalpurNet | H16: Bhubaneswar | I16: 204206 | J16: 10-11-2019 | K16: 5.1 | L16: 1.7 | M16: On Leave | N16: EMP0005
A17: EMP0016 | B17: Sudhansu Behura | C17: F | D17: Product | E17: =PROPER(D17) -> Product | F17: Associate PM | G17: CoastalDev Studio | H17: Berhampur | I17: 89394 | J17: 2021-05-06 | K17: 3.7 | L17: 4.1 | M17: Active | N17: EMP0009
A18: EMP0017 | B18: Sangita Padhi | C18: M | D18: Sales | E18: =PROPER(D18) -> Sales | F18: Sales Manager | G18: CoastalDev Studio | H18: Bhubaneswar | I18: 123031 | J18: 08-11-2023 | K18: 1.2 | L18: 4.8 | M18: Resigned | N18: EMP0006
A19: EMP0018 | B19: Barsha Prusty | C19: male | D19: Engineering | E19: =PROPER(D19) -> Engineering | F19: Architect | G19: BlueLotus IT | H19: Bhubaneswar | I19: 104303 | J19: 20-08-2021 | K19: 3.4 | L19: 1.8 | M19: On Leave | N19: EMP0010
A20: EMP0019 | B20: Lipsa Behura | C20: Female | D20: Data Science | E20: =PROPER(D20) -> Data Science | F20: Data Scientist | G20: UtkalSoft Technologies | H20: Bhubaneswar | I20: 135019 | J20: 20-02-2020 | K20: 4.9 | L20: 3 | M20: Active | N20: EMP0005
A21: EMP0020 | B21: Namita Sahu | C21: male | D21: Marketing | E21: =PROPER(D21) -> Marketing | F21: Digital Marketer | G21: NilGiri Digitals | H21: Puri | I21: 18476 | J21: 09-10-2019 | K21: 5.2 | L21: 4.3 | M21: Active | N21: EMP0013
A22: EMP0021 | B22: Sudhansu Choudhury | C22: M | D22: DevOps | E22: =PROPER(D22) -> Devops | F22: Sr DevOps | G22: TributeAI | H22: Bhubaneswar | I22: 61682 | J22: 09-03-2020 | K22: 4.8 | L22: 4.4 | M22: On Leave | N22: EMP0007
A23: EMP0022 | B23: Sudhansu Mohapatra | C23: Female | D23: Marketing | E23: =PROPER(D23) -> Marketing | F23: Digital Marketer | G23: OdishaCode Labs | H23: Berhampur | I23: 67370 | J23: 28-02-2024 | K23: 0.8 | L23: 3 | M23: Active | N23: EMP0002
... A34: EMP0033 | B34: Priyanka Ratha | C34: F | D34: Engineering | E34: =PROPER(D34) -> Engineering | F34: Tech Lead | G34: InfySoft Bhubaneswar | H34: Puri | I34: 82622 | J34: 22-02-2024 | K34: 0.9 | L34: 4.8 | M34: Active | N34: EMP0004
A35: EMP0034 | B35: Chinmaya Prusty | C35: Male | D35: Sales | E35: =PROPER(D35) -> Sales | F35: Account Manager | G35: InfySoft Bhubaneswar | H35: Bhubaneswar | J35: 19-07-2020 | K35: 4.5 | L35: 3.8 | M35: Active | N35: EMP0018
A36: EMP0035 | B36: Tanmay Padhi | C36: male | D36: Data Science | E36: =PROPER(D36) -> Data Science | F36: Data Analyst | G36: TechNova Solutions | H36: Berhampur | I36: 107257 | J36: 05-02-2023 | K36: 1.9 | L36: 4.9 | M36: Active | N36: EMP0009
A37: EMP0036 | B37: Saurav Biswal | C37: male | D37: Finance | E37: =PROPER(D37) -> Finance | F37: Finance Analyst | G37: InfySoft Bhubaneswar | H37: Rourkela | I37: 169784 | J37: 16-09-2018 | K37: 6.3 | L37: 2.4 | M37: Active | N37: EMP0013
A38: EMP0037 | B38: Saurav Nanda | C38: F | D38: Marketing | E38: =PROPER(D38) -> Marketing | F38: Content Strategist | G38: InfySoft Bhubaneswar | H38: Cuttack | I38: 99048 | J38: 21-09-2018 | K38: 6.3 | L38: 3.1 | M38: On Leave | N38: EMP0018
A39: EMP0038 | B39: Alka Nanda | C39: female | D39: QA | E39: =PROPER(D39) -> Qa | F39: Test Analyst | G39: KalingaTech Pvt Ltd | H39: Puri | I39: 182023 | J39: 07-12-2022 | K39: 2.1 | L39: 4.7 | M39: Resigned | N39: EMP0026
A40: EMP0039 | B40: Puspita Nanda | C40: female | D40: DevOps | E40: =PROPER(D40) -> Devops | F40: Cloud Architect | G40: InfySoft Bhubaneswar | H40: Berhampur | I40: 140041 | J40: 15-06-2021 | K40: 3.6 | L40: 3.4 | M40: Active | N40: EMP0016
A41: EMP0040 | B41: Chinmaya Biswal | C41: male | D41: Marketing | E41: =PROPER(D41) -> Marketing | F41: Digital Marketer | G41: KalingaTech Pvt Ltd | H41: Bhubaneswar | I41: 159138 | J41: 10-08-2023 | K41: 1.4 | L41: 2.9 | M41: Active | N41: EMP0027
A42: EMP0041 | B42: Sangita Ratha | C42: F | D42: DevOps | E42: =PROPER(D42) -> Devops | F42: SRE | G42: SambalpurNet | H42: Bhubaneswar | I42: 25880 | J42: 20-09-2019 | K42: 5.3 | L42: 3.1 | M42: Active | N42: EMP0022
A43: EMP0042 | B43: Sangita Jena | C43: female | D43: Engineering | E43: =PROPER(D43) -> Engineering | F43: Senior Developer | G43: NilGiri Digitals | H43: Cuttack | I43: 68820 | J43: 04-12-2021 | K43: 3.1 | L43: 2.6 | M43: Resigned | N43: EMP0011
A44: EMP0043 | B44: Rahul Ratha | C44: M | D44: Data Science | E44: =PROPER(D44) -> Data Science | F44: Data Analyst | G44: TributeAI | H44: Rourkela | I44: 148155 | J44: 18-01-2020 | K44: 5 | L44: 3.3 | M44: Resigned | N44: EMP0031
A45: EMP0044 | B45: Nirmal Padhi | C45: female | D45: HR | E45: =PROPER(D45) -> Hr | F45: HR Manager | G45: OdishaCode Labs | H45: Puri | I45: 209821 | J45: 2020-05-30 | K45: 4.6 | L45: 2.7 | M45: Active | N45: EMP0041
A46: EMP0045 | B46: Dibya Prusty | C46: M | D46: Engineering | E46: =PROPER(D46) -> Engineering | F46: Architect | G46: SilverByte Systems | H46: Puri | I46: 152528 | J46: 11-03-2020 | K46: 4.8 | L46: 4.3 | M46: Active | N46: EMP0025
A47: EMP0046 | B47: Ipsita Routray | C47: F | D47: HR | E47: =PROPER(D47) -> Hr | F47: Talent Acquisition | G47: SilverByte Systems | H47: Rourkela | I47: 97366 | J47: 21-11-2021 | K47: 3.1 | L47: 2.3 | M47: Active | N47: EMP0036
... A114: EMP0113 | B114: Nirmal Choudhury | C114: male | D114: Marketing | E114: =PROPER(D114) -> Marketing | F114: Content Strategist | G114: SambalpurNet | H114: Berhampur | I114: 46613 | J114: 03-05-2020 | K114: 4.7 | L114: 3.8 | M114: On Leave | N114: EMP0101
A115: EMP0114 | B115: Sudhansu Dhal | C115: M | D115: Sales | E115: =PROPER(D115) -> Sales | F115: Business Developer | G115: TributeAI | H115: Bhubaneswar | I115: 49155 | J115: 26-02-2023 | K115: 1.8 | M115: Active | N115: EMP0014
A116: EMP0115 | B116: Puspita Behura | C116: male | D116: sales | E116: =PROPER(D116) -> Sales | F116: Sales Manager | G116: InfySoft Bhubaneswar | H116: Berhampur | I116: 153126 | J116: 30-04-2018 | K116: 6.7 | L116: 4.7 | M116: On Leave | N116: EMP0092
...

Sheet Projects
A1: Project_ID | B1: Project_Name | C1: Client_Name | D1: Company | E1: Technology_Stack | F1: Budget_Lakhs | G1: Actual_Cost_Lakhs | H1: Start_Date | I1: Deadline | J1: Completion_Date | K1: Status | L1: Team_Size | M1: Billable_Hours | N1: Lead_Employee_ID
A2: PROJ001 | B2: Supply Chain Optimizer | C2: GreenEnergy Co | D2: TechNova Solutions | E2: Android Kotlin | F2: 172.82 | G2: 149.22 | H2: 30-03-2022 | I2: 20-11-2022 | K2: Cancelled | L2: 16 | M2: 7765.2 | N2: EMP0508
A3: PROJ002 | B3: Supply Chain Optimizer | C3: TravelNest | D3: OdishaCode Labs | E3: ML/AI | F3: 123.83 | G3: 158.34 | H3: 01-11-2023 | I3: 28-04-2024 | K3: Cancelled | L3: 4 | M3: 2114.3 | N3: EMP0526
A4: PROJ003 | B4: Data Warehouse Migration | C4: FinServPro | D4: KalingaTech Pvt Ltd | E4: Angular | F4: 110.56 | G4: 114.91 | H4: 07-12-2021 | I4: 13-05-2022 | K4: Under Review | L4: 14 | M4: 1820.4 | N4: EMP0134
A5: PROJ004 | B5: IoT Gateway | C5: GlobalTrade Inc | D5: OdishaCode Labs | E5: AWS | F5: 167.36 | G5: 156.31 | H5: 04-08-2024 | I5: 03-11-2024 | K5: In Progress | L5: 5 | M5: 4444.4 | N5: EMP0530
A6: PROJ005 | B6: IoT Gateway | C6: SmartCity Gov | D6: TributeAI | E6: Flutter | F6: 111.58 | G6: 82.9 | H6: 27-03-2023 | I6: 20-07-2023 | J6: 19-07-2023 | K6: Completed | L6: 16 | M6: 10825.8 | N6: EMP0214
A7: PROJ006 | B7: Smart Grid System | C7: EduSpark | D7: InfySoft Bhubaneswar | E7: Node.js | F7: 167.64 | G7: 168.44 | H7: 05-03-2021 | I7: 06-10-2021 | K7: In Progress | L7: 17 | M7: 5174.3 | N7: EMP0161
A8: PROJ007 | B8: Fleet Management | C8: GlobalTrade Inc | D8: UtkalSoft Technologies | E8: ML/AI | F8: 78.19 | G8: 69.7 | H8: 04-09-2021 | I8: 10-11-2021 | K8: Under Review | L8: 15 | M8: 10820.4 | N8: EMP0105
A9: PROJ008 | B9: Smart Grid System | C9: FinServPro | D9: InfySoft Bhubaneswar | E9: iOS Swift | F9: 101.73 | G9: 115.49 | H9: 26-10-2023 | I9: 08-04-2024 | K9: Under Review | L9: 8 | M9: 5141.9 | N9: EMP0241
A10: PROJ009 | B10: Analytics Dashboard | C10: GlobalTrade Inc | D10: OdishaCode Labs | E10: Data Engineering | F10: 96.83 | G10: 89.11 | H10: 19-08-2022 | I10: 18-01-2023 | K10: On Hold | L10: 3 | M10: 458.3 | N10: EMP0414
A11: PROJ010 | B11: Supply Chain Optimizer | C11: LogiTrack | D11: BlueLotus IT | E11: .NET | F11: 63.75 | G11: 59.08 | H11: 23-07-2024 | I11: 06-12-2024 | K11: Under Review | L11: 4 | M11: 3512.1 | N11: EMP0508
A12: PROJ011 | B12: DigitalBank Portal | C12: SmartCity Gov | D12: BlueLotus IT | E12: Azure | F12: 16.57 | G12: 20.44 | H12: 07-10-2022 | I12: 08-08-2023 | K12: In Progress | L12: 18 | M12: 12125.9 | N12: EMP0291
A13: PROJ012 | B13: Smart Grid System | C13: GreenEnergy Co | D13: InfySoft Bhubaneswar | E13: DevOps/K8s | F13: 10.59 | G13: 10.16 | H13: 17-02-2023 | I13: 16-06-2023 | K13: Cancelled | L13: 23 | M13: 18151.5 | N13: EMP0352
A14: PROJ013 | B14: HR Automation Suite | C14: FinServPro | D14: CoastalDev Studio | E14: Azure | F14: 9.07 | G14: 10.12 | H14: 24-08-2022 | I14: 21-03-2023 | K14: On Hold | L14: 14 | M14: 8129.3 | N14: EMP0094
A15: PROJ014 | B15: Analytics Dashboard | C15: MediCare Systems | D15: SilverByte Systems | E15: DevOps/K8s | F15: 139.64 | G15: 171.38 | H15: 04-03-2023 | I15: 20-12-2023 | K15: On Hold | L15: 16 | M15: 5854.7 | N15: EMP0371
A16: PROJ015 | B16: DigitalBank Portal | C16: GreenEnergy Co | D16: UtkalSoft Technologies | E16: Node.js | F16: 57.32 | G16: 74.5 | H16: 06-05-2023 | I16: 15-07-2023 | K16: On Hold | L16: 8 | M16: 2307 | N16: EMP0538
A17: PROJ016 | B17: Analytics Dashboard | C17: TravelNest | D17: SambalpurNet | E17: Salesforce | F17: 190.76 | G17: 200.88 | H17: 12-02-2023 | I17: 08-05-2023 | K17: Under Review | L17: 24 | M17: 17402.8 | N17: EMP0119
A18: PROJ017 | B18: IoT Gateway | C18: AutoDrive | D18: UtkalSoft Technologies | E18: React | F18: 61.25 | G18: 53.5 | H18: 10-02-2021 | I18: 18-07-2021 | K18: Cancelled | L18: 9 | M18: 7651.3 | N18: EMP0540
... A37: PROJ036 | B37: DigitalBank Portal | C37: TravelNest | D37: KalingaTech Pvt Ltd | E37: Azure | F37: 82.32 | G37: 97.59 | H37: 21-07-2022 | I37: 06-07-2023 | K37: Cancelled | L37: 16 | M37: 1988 | N37: EMP0321
A38: PROJ037 | B38: Analytics Dashboard | C38: EduSpark | D38: SilverByte Systems | E38: iOS Swift | F38: 55.06 | G38: 57.15 | H38: 21-11-2022 | I38: 16-06-2023 | J38: 02-06-2023 | K38: Completed | L38: 5 | M38: 3111 | N38: EMP0390
A39: PROJ038 | B39: Fleet Management | C39: InsureNow | D39: InfySoft Bhubaneswar | E39: iOS Swift | F39: 19.87 | G39: 16.01 | H39: 24-12-2023 | I39: 28-06-2024 | K39: On Hold | L39: 18 | M39: 4154.7 | N39: EMP0010
A40: PROJ039 | B40: Smart Grid System | C40: RetailPlus | D40: InfySoft Bhubaneswar | E40: AWS | F40: 52.99 | G40: 49.34 | H40: 23-02-2021 | I40: 18-09-2021 | K40: On Hold | L40: 14 | M40: 7275.9 | N40: EMP0429
A41: PROJ040 | B41: Inventory Tracker | C41: SportsPro | D41: TechNova Solutions | E41: Salesforce | F41: 38.03 | G41: 31.61 | H41: 03-07-2021 | I41: 09-02-2022 | K41: In Progress | L41: 11 | M41: 1228.3 | N41: EMP0279
A42: PROJ041 | B42: ML Fraud Detection | C42: SportsPro | D42: BlueLotus IT | E42: Data Engineering | F42: 93.95 | G42: 94.74 | H42: 01-07-2022 | I42: 12-11-2022 | K42: Cancelled | L42: 15 | M42: 7707.2 | N42: EMP0096
A43: PROJ042 | B43: E-Commerce Platform | C43: FinServPro | D43: ZeroOneSystems | E43: iOS Swift | F43: 183.85 | G43: 234.02 | H43: 14-03-2024 | I43: 22-08-2024 | K43: In Progress | L43: 9 | M43: 2621 | N43: EMP0337
A44: PROJ043 | B44: Talent Management | C44: EduSpark | D44: OdishaCode Labs | E44: React | F44: 23.27 | G44: 20.03 | H44: 19-10-2022 | I44: 04-08-2023 | K44: Cancelled | L44: 14 | M44: 2340.5 | N44: EMP0180
A45: PROJ044 | B45: Supply Chain Optimizer | C45: GlobalTrade Inc | D45: SambalpurNet | E45: Azure | F45: 59.86 | G45: 42.4 | H45: 09-06-2021 | I45: 08-05-2022 | K45: On Hold | L45: 4 | M45: 2436.2 | N45: EMP0499
A46: PROJ045 | B46: E-Commerce Platform | C46: InsureNow | D46: CoastalDev Studio | E46: AWS | F46: 166.14 | G46: 137.43 | H46: 23-07-2024 | I46: 28-04-2025 | K46: On Hold | L46: 24 | M46: 19549.7 | N46: EMP0371
A47: PROJ046 | B47: HR Automation Suite | C47: RetailPlus | D47: NilGiri Digitals | E47: DevOps/K8s | F47: 17 | G47: 19.66 | H47: 15-01-2024 | I47: 05-08-2024 | K47: Cancelled | L47: 16 | M47: 10245.3 | N47: EMP0447
A48: PROJ047 | B48: Inventory Tracker | C48: BankFirst Ltd | D48: TributeAI | E48: iOS Swift | F48: 151.97 | G48: 162.7 | H48: 15-12-2024 | I48: 01-11-2025 | K48: Under Review | L48: 5 | M48: 4070.4 | N48: EMP0216
A49: PROJ048 | B49: Data Warehouse Migration | C49: LogiTrack | D49: NilGiri Digitals | E49: Angular | F49: 165.98 | G49: 150.33 | H49: 31-05-2023 | I49: 02-10-2023 | K49: Under Review | L49: 23 | M49: 18188.4 | N49: EMP0003
A50: PROJ049 | B50: LMS Portal | C50: BankFirst Ltd | D50: SilverByte Systems | E50: DevOps/K8s | F50: 191.68 | G50: 192.46 | H50: 28-12-2024 | I50: 16-10-2025 | K50: On Hold | L50: 4 | M50: 1183.6 | N50: EMP0264
A51: PROJ050 | B51: Cloud Migration | C51: InsureNow | D51: KalingaTech Pvt Ltd | E51: Salesforce | F51: 22.2 | G51: 27.12 | H51: 12-10-2022 | I51: 20-12-2022 | K51: On Hold | L51: 24 | M51: 19237.2 | N51: EMP0142
A52: PROJ051 | B52: Inventory Tracker | C52: SmartCity Gov | D52: BlueLotus IT | E52: Data Engineering | F52: 187.09 | G52: 217.27 | H52: 06-05-2023 | I52: 31-12-2023 | J52: 17-12-2023 | K52: Completed | L52: 3 | M52: 1263.6 | N52: EMP0024
A53: PROJ052 | B53: Real-Time Reporting | C53: BankFirst Ltd | D53: TechNova Solutions | E53: Salesforce | F53: 189.62 | G53: 214.88 | H53: 27-04-2024 | I53: 13-02-2025 | K53: In Progress | L53: 22 | M53: 9937.5 | N53: EMP0337
A54: PROJ053 | B54: DigitalBank Portal | C54: MediCare Systems | D54: TechNova Solutions | E54: AWS | F54: 109.35 | G54: 101.38 | H54: 12-04-2022 | I54: 12-04-2023 | K54: On Hold | L54: 10 | M54: 8136.3 | N54: EMP0131
A55: PROJ054 | B55: IoT Gateway | C55: EduSpark | D55: NilGiri Digitals | E55: React | F55: 16.93 | G55: 21.91 | H55: 08-03-2022 | I55: 01-07-2022 | K55: Under Review | L55: 13 | M55: 11014.5 | N55: EMP0049
A56: PROJ055 | B56: Fleet Management | C56: FinServPro | D56: SilverByte Systems | E56: React | F56: 176.7 | G56: 159.98 | H56: 22-01-2022 | I56: 14-01-2023 | J56: 19-12-2022 | K56: Completed | L56: 9 | M56: 6364.8 | N56: EMP0215
A57: PROJ056 | B57: Talent Management | C57: RetailPlus | D57: CoastalDev Studio | E57: Java | F57: 9.9 | G57: 8.9 | H57: 17-01-2023 | I57: 22-09-2023 | K57: On Hold | L57: 25 | M57: 22353.9 | N57: EMP0152
A58: PROJ057 | B58: Analytics Dashboard | C58: TravelNest | D58: ZeroOneSystems | E58: AWS | F58: 79.99 | G58: 72.56 | H58: 26-06-2023 | I58: 30-05-2024 | K58: In Progress | L58: 9 | M58: 5178.9 | N58: EMP0595
...

Sheet Attendance
A1: Employee_ID | B1: Record_ID | C1: Date | D1: Login_Time | E1: Logout_Time | F1: Work_Hours | G1: Status | H1: WFH_Flag
A2: EMP0076 | B2: ATT00001 | C2: 02-09-2024 | D2: 0.34791667 | E2: 14:21 | F2: 6.9 | G2: Present | H2: no
A3: EMP0076 | B3: ATT00002 | C3: 03-09-2024 | D3: 10:30 | E3: 17:30 | F3: 7.78 | G3: Present | H3: yes
A4: EMP0076 | B4: ATT00003 | C4: 04-09-2024 | G4: Absent | H4: no
A5: EMP0076 | B5: ATT00004 | C5: 05-09-2024 | D5: 08:40 | E5: 17:40 | F5: 9.99 | G5: Present | H5: no
A6: EMP0076 | B6: ATT00005 | C6: 06-09-2024 | D6: 09:22 | E6: 19:22 | F6: 10.75 | G6: Present | H6: Yes
A7: EMP0076 | B7: ATT00006 | C7: 09-09-2024 | D7: 09:57 | E7: 16:57 | F7: 7.23 | G7: Present | H7: no
A8: EMP0076 | B8: ATT00007 | C8: 10-09-2024 | D8: 10:02 | E8: 21:02 | F8: 11.44 | G8: Present | H8: yes
A9: EMP0076 | B9: ATT00008 | C9: 11-09-2024 | D9: 10:11 | E9: 16:11 | F9: 6.6 | G9: Present | H9: no
A10: EMP0076 | B10: ATT00009 | C10: 12-09-2024 | D10: 08:47 | E10: 17:47 | F10: 9.87 | G10: Present | H10: No
A11: EMP0076 | B11: ATT00010 | C11: 13-09-2024 | D11: 08:52 | E11: 14:52 | F11: 6.69 | G11: Present | H11: Yes
A12: EMP0076 | B12: ATT00011 | C12: 16-09-2024 | D12: 10:47 | E12: 19:47 | F12: 9.38 | G12: Present | H12: Yes
A13: EMP0076 | B13: ATT00012 | C13: 17-09-2024 | D13: 10:06 | E13: 20:06 | F13: 10.03 | G13: Present | H13: yes
A14: EMP0076 | B14: ATT00013 | C14: 18-09-2024 | D14: 08:51 | E14: 17:51 | F14: 9.92 | G14: Present | H14: Yes
A15: EMP0076 | B15: ATT00014 | C15: 19-09-2024 | D15: 10:55 | E15: 21:55 | F15: 11.21 | G15: Present | H15: Yes
A16: EMP0076 | B16: ATT00015 | C16: 20-09-2024 | D16: 10:08 | E16: 20:08 | F16: 10.73 | G16: Present | H16: No
... A18: EMP0076 | B18: ATT00017 | C18: 24-09-2024 | D18: 09:39 | E18: 17:39 | F18: 8.28 | G18: Present | H18: No
A19: EMP0076 | B19: ATT00018 | C19: 25-09-2024 | G19: Half Day | H19: no
A20: EMP0076 | B20: ATT00019 | C20: 26-09-2024 | D20: 08:30 | E20: 19:30 | F20: 11.18 | G20: Present | H20: no
A21: EMP0076 | B21: ATT00020 | C21: 27-09-2024 | D21: 09:53 | E21: 16:53 | F21: 7.89 | G21: Present | H21: Yes
A22: EMP0076 | B22: ATT00021 | C22: 30-09-2024 | D22: 08:21 | E22: 18:21 | F22: 10.33 | G22: Present | H22: No
A23: EMP0076 | B23: ATT00022 | C23: 01-10-2024 | D23: 09:09 | E23: 16:09 | F23: 7.45 | G23: Present | H23: no
A24: EMP0076 | B24: ATT00023 | C24: 02-10-2024 | D24: 09:39 | E24: 18:39 | F24: 9.82 | G24: Present | H24: no
A25: EMP0076 | B25: ATT00024 | C25: 03-10-2024 | D25: 08:00 | E25: 17:00 | F25: 9.05 | G25: Present | H25: No
A26: EMP0076 | B26: ATT00025 | C26: 04-10-2024 | D26: 08:32 | E26: 15:32 | F26: 7.62 | G26: Present | H26: yes
A27: EMP0076 | B27: ATT00026 | C27: 07-10-2024 | D27: 10:55 | E27: 17:55 | F27: 7.45 | G27: Present | H27: Yes
A28: EMP0076 | B28: ATT00027 | C28: 08-10-2024 | D28: 09:36 | E28: 18:36 | F28: 9.31 | G28: Present | H28: No
A29: EMP0076 | B29: ATT00028 | C29: 2024/10/09 | D29: 09:05 | E29: 17:05 | F29: 8.44 | G29: Present | H29: No
A30: EMP0076 | B30: ATT00029 | C30: 10-10-2024 | D30: 09:52 | E30: 16:52 | F30: 7.26 | G30: Present | H30: yes
A31: EMP0076 | B31: ATT00030 | C31: 11-10-2024 | D31: 10:08 | E31: 20:08 | F31: 10.71 | G31: Present | H31: no
... A56: EMP0061 | B56: ATT00055 | C56: 17-09-2024 | D56: 10:59 | E56: 16:59 | F56: 6.51 | G56: Present | H56: Yes
A57: EMP0061 | B57: ATT00056 | C57: 18-09-2024 | G57: Leave | H57: Yes
A58: EMP0061 | B58: ATT00057 | C58: 19-09-2024 | D58: 10:05 | E58: 17:05 | F58: 7.08 | G58: Present | H58: No
A59: EMP0061 | B59: ATT00058 | C59: 20-09-2024 | D59: 08:32 | E59: 15:32 | F59: 7.7 | G59: Present | H59: Yes
A60: EMP0061 | B60: ATT00059 | C60: 23-09-2024 | D60: 09:00 | E60: 18:00 | F60: 9.57 | G60: Present | H60: no
A61: EMP0061 | B61: ATT00060 | C61: 24-09-2024 | D61: 10:33 | E61: 20:33 | F61: 10.48 | G61: Present | H61: Yes
A62: EMP0061 | B62: ATT00061 | C62: 25-09-2024 | D62: 09:05 | E62: 17:05 | F62: 8.99 | G62: Present | H62: no
A63: EMP0061 | B63: ATT00062 | C63: 26-09-2024 | D63: 09:57 | E63: 16:57 | F63: 7.9 | G63: Present | H63: yes
A64: EMP0061 | B64: ATT00063 | C64: 27-09-2024 | D64: 10:57 | E64: 20:57 | F64: 10.09 | G64: Present | H64: no
A65: EMP0061 | B65: ATT00064 | C65: 30-09-2024 | D65: 08:08 | E65: 19:08 | F65: 11.43 | G65: Present | H65: no
...

Sheet Hiring
A1: Candidate_ID | B1: Full_Name | C1: Applied_Role | D1: Department | F1: Source | H1: Interview_Round1_Score | I1: Interview_Round2_Score | J1: Final_Score | K1: Expected_Salary | L1: Offered_Salary | M1: Offer_Status | N1: Interview_Date | O1: Company | P1: Years_Experience
A2: CAND0001 | B2: Abhishek Ratha | C2: Product Manager | D2: Data Science | E2: =PROPER(D2) -> Data Science | F2: Job Portal | G2: =PROPER(F2) -> Job Portal | H2: 3.8 | I2: 7.9 | J2: 5.8 | K2: 123018 | L2: 135000 | M2: Pending | N2: 08-04-2024 | O2: SambalpurNet | P2: 4.7
A3: CAND0002 | B3: Bikash Behura | C3: DevOps Engineer | D3: Data Science | E3: =PROPER(D3) -> Data Science | F3: LinkedIn | G3: =PROPER(F3) -> Linkedin | H3: 3.1 | I3: 3.3 | J3: 3.2 | K3: 139712 | L3: 132960 | M3: Accepted | N3: 27-05-2024 | O3: TechNova Solutions | P3: 5.7
A4: CAND0003 | B4: Ankita Behura | C4: HR Executive | D4: Engineering | E4: =PROPER(D4) -> Engineering | F4: linkedin | G4: =PROPER(F4) -> Linkedin | H4: 4.1 | I4: 6.7 | J4: 5.4 | K4: 26013 | L4: 28384 | M4: Pending | N4: 18-09-2024 | O4: TechNova Solutions | P4: 14.5
A5: CAND0004 | B5: Sudhansu Prusty | C5: DevOps Engineer | D5: HR | E5: =PROPER(D5) -> Hr | F5: Campus | G5: =PROPER(F5) -> Campus | H5: 3.5 | I5: 8.8 | J5: 6.2 | K5: 176914 | L5: 170600 | M5: Pending | N5: 11-12-2023 | O5: CoastalDev Studio | P5: 11.7
A6: CAND0005 | B6: Puspita Pattnaik | C6: QA Engineer | D6: DevOps | E6: =PROPER(D6) -> Devops | F6: LinkedIn | G6: =PROPER(F6) -> Linkedin | H6: 3.1 | I6: 7.9 | J6: 5.5 | K6: 155983 | L6: 164134 | M6: Withdrawn | N6: 13-12-2024 | O6: OdishaCode Labs | P6: 7
A7: CAND0006 | B7: Soumya Senapati | C7: Product Manager | D7: Sales | E7: =PROPER(D7) -> Sales | F7: Walk-in | G7: =PROPER(F7) -> Walk-In | H7: 4.3 | I7: 9.6 | J7: 6.9 | K7: 37894 | L7: 39365 | M7: Accepted | N7: 28-04-2023 | O7: SambalpurNet | P7: 4.3
A8: CAND0007 | B8: Satyajit Padhi | C8: DevOps Engineer | D8: Product | E8: =PROPER(D8) -> Product | F8: LinkedIn | G8: =PROPER(F8) -> Linkedin | I8: 8.5 | K8: 164283 | L8: 170751 | M8: Accepted | N8: 01-02-2023 | O8: UtkalSoft Technologies | P8: 11
A9: CAND0008 | B9: Sudhansu Biswal | C9: Cloud Architect | D9: Data Science | E9: =PROPER(D9) -> Data Science | F9: Job Portal | G9: =PROPER(F9) -> Job Portal | H9: 8.1 | I9: 4.2 | J9: 6.2 | K9: 86255 | M9: Rejected | N9: 23-09-2024 | O9: ZeroOneSystems | P9: 13
A10: CAND0009 | B10: Smita Sahu | C10: HR Executive | D10: DevOps | E10: =PROPER(D10) -> Devops | F10: linkedin | G10: =PROPER(F10) -> Linkedin | H10: 4.3 | I10: 4.8 | J10: 4.5 | K10: 24144 | L10: 25381 | M10: Accepted | N10: 18-05-2023 | O10: BlueLotus IT | P10: 8.8
A11: CAND0010 | B11: Nirmal Ratha | C11: Business Analyst | D11: QA | E11: =PROPER(D11) -> Qa | F11: Campus | G11: =PROPER(F11) -> Campus | H11: 7.5 | I11: 6.9 | J11: 7.2 | K11: 191563 | M11: Withdrawn | N11: 28-08-2024 | O11: ZeroOneSystems | P11: 5.9
A12: CAND0011 | B12: Nirmal Padhi | C12: Product Manager | D12: DevOps | E12: =PROPER(D12) -> Devops | F12: Campus | G12: =PROPER(F12) -> Campus | H12: 7.4 | I12: 3.3 | J12: 5.3 | K12: 170124 | L12: 160467 | M12: Accepted | N12: 13-10-2024 | O12: KalingaTech Pvt Ltd | P12: 9
A13: CAND0012 | B13: Nirmal Padhi | C13: Product Manager | D13: QA | E13: =PROPER(D13) -> Qa | F13: linkedin | G13: =PROPER(F13) -> Linkedin | H13: 9.6 | I13: 9.1 | J13: 9.3 | K13: 108417 | L13: 122402 | M13: Negotiating | N13: 20-10-2024 | O13: TributeAI | P13: 6.5
A14: CAND0013 | B14: Tapas Dhal | C14: Sales Manager | D14: DevOps | E14: =PROPER(D14) -> Devops | F14: LinkedIn | G14: =PROPER(F14) -> Linkedin | H14: 8.8 | I14: 8.6 | J14: 8.7 | L14: 166699 | M14: Pending | N14: 13-07-2023 | O14: SambalpurNet | P14: 11.2
A15: CAND0014 | B15: Abhishek Prusty | C15: Sales Manager | D15: Product | E15: =PROPER(D15) -> Product | F15: Naukri | G15: =PROPER(F15) -> Naukri | H15: 7 | I15: 8.8 | J15: 7.9 | K15: 144314 | L15: 135340 | M15: Rejected | N15: 02-09-2023 | O15: NilGiri Digitals | P15: 7.6
A16: CAND0015 | B16: Smita Prusty | C16: Software Engineer | D16: DevOps | E16: =PROPER(D16) -> Devops | F16: LinkedIn | G16: =PROPER(F16) -> Linkedin | H16: 3.1 | I16: 8.5 | J16: 5.8 | M16: Accepted | N16: 13-03-2023 | O16: TechNova Solutions | P16: 9.8
A17: CAND0016 | B17: Ankita Choudhury | C17: Sales Manager | D17: HR | E17: =PROPER(D17) -> Hr | F17: linkedin | G17: =PROPER(F17) -> Linkedin | H17: 9 | I17: 4.8 | J17: 6.9 | K17: 75018 | L17: 70245 | M17: Accepted | N17: 08-12-2023 | O17: SilverByte Systems | P17: 4.9
A18: CAND0017 | B18: Sudhansu Sahu | C18: HR Executive | D18: Design | E18: =PROPER(D18) -> Design | F18: LinkedIn | G18: =PROPER(F18) -> Linkedin | H18: 4 | I18: 4 | J18: 4 | K18: 134338 | L18: 151435 | M18: Accepted | N18: 27-08-2023 | O18: ZeroOneSystems | P18: 10
A19: CAND0018 | B19: Tanmay Padhi | C19: Business Analyst | D19: Engineering | E19: =PROPER(D19) -> Engineering | F19: naukri | G19: =PROPER(F19) -> Naukri | H19: 8.8 | I19: 6.4 | J19: 7.6 | K19: 75363 | M19: Pending | N19: 29-10-2023 | O19: OdishaCode Labs | P19: 8.2
A20: CAND0019 | B20: Chinmaya Mishra | C20: DevOps Engineer | D20: Finance | E20: =PROPER(D20) -> Finance | F20: naukri | G20: =PROPER(F20) -> Naukri | H20: 4.5 | I20: 4.4 | J20: 4.5 | K20: 60126 | M20: Rejected | N20: 08-05-2024 | O20: InfySoft Bhubaneswar | P20: 5
A21: CAND0020 | B21: Dibya Routray | C21: Cloud Architect | D21: Product | E21: =PROPER(D21) -> Product | F21: LinkedIn | G21: =PROPER(F21) -> Linkedin | H21: 5.5 | I21: 7.3 | J21: 6.4 | K21: 67215 | L21: 58147 | M21: Rejected | N21: 11-09-2023 | O21: TechNova Solutions | P21: 0.9
A22: CAND0021 | B22: Ankita Prusty | C22: Business Analyst | D22: Engineering | E22: =PROPER(D22) -> Engineering | F22: Walk-in | G22: =PROPER(F22) -> Walk-In | H22: 8.5 | I22: 7.6 | J22: 8.1 | K22: 113954 | M22: Rejected | N22: 14-05-2024 | O22: NilGiri Digitals | P22: 11.7
A23: CAND0022 | B23: Satyajit Pattnaik | C23: Sales Manager | D23: Marketing | E23: =PROPER(D23) -> Marketing | F23: Job Portal | G23: =PROPER(F23) -> Job Portal | H23: 6.5 | I23: 9.1 | J23: 7.8 | K23: 183795 | L23: 208454 | M23: Accepted | N23: 26-07-2023 | O23: OdishaCode Labs | P23: 4.8
A24: CAND0023 | B24: Rahul Nanda | C24: Product Manager | D24: Sales | E24: =PROPER(D24) -> Sales | F24: Naukri | G24: =PROPER(F24) -> Naukri | H24: 5.5 | I24: 8.6 | J24: 7 | K24: 64504 | M24: Pending | N24: 26-11-2023 | O24: BlueLotus IT | P24: 11.4
A25: CAND0024 | B25: Rajan Dhal | C25: Product Manager | D25: Finance | E25: =PROPER(D25) -> Finance | F25: Naukri | G25: =PROPER(F25) -> Naukri | H25: 3.8 | I25: 5.5 | J25: 4.7 | K25: 196050 | L25: 225137 | M25: Accepted | N25: 05-04-2024 | O25: KalingaTech Pvt Ltd | P25: 8.7
A26: CAND0025 | B26: Puspita Dhal | C26: Sales Manager | D26: Sales | E26: =PROPER(D26) -> Sales | F26: linkedin | G26: =PROPER(F26) -> Linkedin | H26: 6.7 | I26: 3.7 | J26: 5.2 | K26: 66622 | L26: 66872 | M26: Rejected | N26: 03-04-2024 | O26: KalingaTech Pvt Ltd | P26: 5.1
A27: CAND0026 | B27: Ankita Mishra | C27: HR Executive | D27: Marketing | E27: =PROPER(D27) -> Marketing | F27: Referral | G27: =PROPER(F27) -> Referral | H27: 3.1 | I27: 4.3 | J27: 3.7 | K27: 60845 | L27: 66284 | M27: Negotiating | N27: 23-10-2023 | O27: SilverByte Systems | P27: 5.9
A28: CAND0027 | B28: Namita Biswal | C28: QA Engineer | D28: QA | E28: =PROPER(D28) -> Qa | F28: Job Portal | G28: =PROPER(F28) -> Job Portal | H28: 3.4 | I28: 9 | J28: 6.2 | K28: 129397 | L28: 117989 | M28: Accepted | N28: 21-09-2023 | O28: OdishaCode Labs | P28: 11.7
A29: CAND0028 | B29: Ranjit Parida | C29: DevOps Engineer | D29: DevOps | E29: =PROPER(D29) -> Devops | F29: Campus | G29: =PROPER(F29) -> Campus | H29: 4.2 | I29: 5.2 | J29: 4.7 | K29: 199530 | M29: Pending | N29: 30-11-2024 | O29: KalingaTech Pvt Ltd | P29: 9.2
A30: CAND0029 | B30: Namita Behura | C30: HR Executive | D30: DevOps | E30: =PROPER(D30) -> Devops | F30: Naukri | G30: =PROPER(F30) -> Naukri | H30: 6.6 | I30: 4.2 | J30: 5.4 | K30: 169961 | L30: 185498 | M30: Accepted | N30: 24-09-2024 | O30: SilverByte Systems | P30: 11.6
A31: CAND0030 | B31: Soumya Prusty | C31: Sales Manager | D31: Sales | E31: =PROPER(D31) -> Sales | F31: Job Portal | G31: =PROPER(F31) -> Job Portal | H31: 8.5 | I31: 5.5 | J31: 7 | K31: 131761 | L31: 125277 | M31: Negotiating | N31: 17-06-2023 | O31: TechNova Solutions | P31: 11.3
A32: CAND0031 | B32: Nirmal Mishra | C32: QA Engineer | D32: Sales | E32: =PROPER(D32) -> Sales | F32: naukri | G32: =PROPER(F32) -> Naukri | H32: 9.7 | I32: 8.8 | J32: 9.2 | K32: 180507 | L32: 193212 | M32: Accepted | N32: 02-04-2023 | O32: SilverByte Systems | P32: 6.8
A33: CAND0032 | B33: Subhasree Parida | C33: Cloud Architect | D33: Data Science | E33: =PROPER(D33) -> Data Science | F33: Referral | G33: =PROPER(F33) -> Referral | H33: 3.8 | I33: 6.2 | J33: 5 | K33: 158520 | L33: 151325 | M33: Pending | N33: 10-03-2023 | O33: KalingaTech Pvt Ltd | P33: 4.3
A34: CAND0033 | B34: Debasmita Mohapatra | C34: Product Manager | D34: Design | E34: =PROPER(D34) -> Design | F34: Campus | G34: =PROPER(F34) -> Campus | H34: 9.8 | I34: 8.5 | J34: 9.2 | K34: 125983 | L34: 129695 | M34: Negotiating | N34: 21-05-2023 | O34: ZeroOneSystems | P34: 6.3
A35: CAND0034 | B35: Ipsita Behura | C35: Sales Manager | D35: Sales | E35: =PROPER(D35) -> Sales | F35: LinkedIn | G35: =PROPER(F35) -> Linkedin | H35: 4.5 | J35: 4.5 | K35: 103827 | L35: 117799 | M35: Rejected | N35: 26-12-2024 | O35: SilverByte Systems | P35: 9.8
A36: CAND0035 | B36: Lipsa Tripathy | C36: Data Analyst | D36: HR | E36: =PROPER(D36) -> Hr | F36: naukri | G36: =PROPER(F36) -> Naukri | H36: 7.7 | I36: 5.9 | J36: 6.8 | K36: 131980 | M36: Withdrawn | N36: 09-04-2024 | O36: UtkalSoft Technologies | P36: 13.5
A37: CAND0036 | B37: Rajan Routray | C37: UI Designer | D37: Marketing | E37: =PROPER(D37) -> Marketing | F37: naukri | G37: =PROPER(F37) -> Naukri | H37: 5.3 | I37: 9.5 | J37: 7.4 | K37: 83588 | L37: 91424 | M37: Withdrawn | N37: 18-04-2024 | O37: SilverByte Systems | P37: 4.8
A38: CAND0037 | B38: Subhasree Padhi | C38: HR Executive | D38: Engineering | E38: =PROPER(D38) -> Engineering | F38: LinkedIn | G38: =PROPER(F38) -> Linkedin | H38: 6.1 | I38: 6.2 | J38: 6.2 | K38: 139840 | L38: 125731 | M38: Rejected | N38: 24-10-2024 | O38: CoastalDev Studio | P38: 11.7
A39: CAND0038 | B39: Amlan Biswal | C39: UI Designer | D39: Sales | E39: =PROPER(D39) -> Sales | F39: Referral | G39: =PROPER(F39) -> Referral | H39: 7.9 | I39: 3.3 | J39: 5.6 | K39: 100081 | L39: 89054 | M39: Negotiating | N39: 06-07-2024 | O39: CoastalDev Studio | P39: 3.9
A40: CAND0039 | B40: Subhasree Sahu | C40: Cloud Architect | D40: Sales | E40: =PROPER(D40) -> Sales | F40: Campus | G40: =PROPER(F40) -> Campus | H40: 5.7 | I40: 3.9 | J40: 4.8 | M40: Negotiating | N40: 05-01-2024 | O40: BlueLotus IT | P40: 0.7
...

Sheet KPL_Summary
A1: 📊 BHUBANESWAR TECH — TEAM & COMPANY KPI METRICS
A3: Quarter | B3: Year | C3: Company | D3: Total_Employees | E3: Active_Employees | F3: Resigned_Employees | G3: Attrition_Pct | H3: New_Hires | I3: Avg_Performance_Rating | J3: Billable_Hours_Total | K3: Revenue_Contribution_Lakhs | L3: Avg_Salary_Monthly | M3: Avg_Interview_Score
A4: Q1 | B4: 2022 | C4: NilGiri Digitals | D4: 249 | E4: 233 | F4: 16 | G4: 6.43 | H4: 40 | I4: 3.11 | J4: 10192.5 | K4: 21457.42 | L4: 61353 | M4: 6.72
A5: Q1 | B5: 2022 | C5: TechNova Solutions | D5: 83 | E5: 63 | F5: 20 | G5: 24.1 | H5: 15 | I5: 3.67 | J5: 4423 | K5: 4529.78 | L5: 44142 | M5: 7.41
A6: Q1 | B6: 2022 | C6: CoastalDev Studio | D6: 192 | E6: 176 | F6: 16 | G6: 8.33 | H6: 21 | I6: 3.59 | J6: 4247.7 | K6: 7652.85 | L6: 83712 | M6: 5.84
A7: Q1 | B7: 2022 | C7: ZeroOneSystems | D7: 232 | E7: 229 | F7: 3 | G7: 1.29 | H7: 27 | I7: 3.94 | J7: 8246.6 | K7: 16759.42 | L7: 68983 | M7: 7.6
A8: Q1 | B8: 2022 | C8: InfySoft Bhubaneswar | D8: 115 | E8: 101 | F8: 14 | G8: 12.17 | H8: 9 | I8: 3.99 | J8: 5634.8 | K8: 3750.14 | L8: 62396 | M8: 7.24
A9: Q1 | B9: 2022 | C9: OdishaCode Labs | D9: 116 | E9: 111 | F9: 5 | G9: 4.31 | H9: 36 | I9: 4.62 | J9: 10783.2 | K9: 21845.3 | L9: 117012 | M9: 8.2
A10: Q2 | B10: 2022 | C10: SambalpurNet | D10: 99 | E10: 93 | F10: 6 | G10: 6.06 | H10: 31 | I10: 4.63 | J10: 12970.4 | K10: 17454.6 | L10: 114211 | M10: 5.61
A11: Q2 | B11: 2022 | C11: TechNova Solutions | D11: 290 | E11: 278 | F11: 12 | G11: 4.14 | H11: 36 | I11: 3.98 | J11: 7389.1 | K11: 16217.95 | L11: 63493 | M11: 7.43
A12: Q2 | B12: 2022 | C12: InfySoft Bhubaneswar | D12: 157 | E12: 143 | F12: 14 | G12: 8.92 | H12: 34 | I12: 4.62 | J12: 7544.8 | K12: 15525.89 | L12: 53608 | M12: 6.01
A13: Q2 | B13: 2022 | C13: BlueLotus IT | D13: 74 | E13: 69 | F13: 5 | G13: 6.76 | H13: 15 | I13: 3.5 | J13: 9302.4 | K13: 6177.5 | L13: 109789 | M13: 7.19
A14: Q2 | B14: 2022 | C14: CoastalDev Studio | D14: 197 | E14: 179 | F14: 18 | G14: 9.14 | H14: 24 | I14: 4.62 | J14: 10961.5 | K14: 7701.38 | L14: 92663 | M14: 5.73
A15: Q2 | B15: 2022 | C15: SilverByte Systems | D15: 202 | E15: 187 | F15: 15 | G15: 7.43 | H15: 37 | I15: 3.37 | J15: 4062.8 | K15: 8060.16 | L15: 115046 | M15: 8.26
... A75: Q4 | B75: 2024 | C75: KalingaTech Pvt Ltd | D75: 171 | E75: 151 | F75: 20 | G75: 11.7 | H75: 33 | I75: 3.65 | J75: 4758.8 | K75: 9837.24 | L75: 96140 | M75: 6.77

Sheet All answers
B1: 📋 BHUBANESWAR TECH DATASET — PRACTICE QUESTIONS | F1: Performance_Rating | G1: (9)Create a column 'Performance_Band': Rating ≥ 4.5 → 'Excellent', 3.5–4.4 → 'Good', < 3.5 → 'Needs Improvement'. Use IFS. | I1: Budget_Lakhs | J1: Actual_Cost_Lakhs | K1: (10)In Projects sheet, flag projects where Actual_Cost > Budget as 'Over Budget', else 'Within Budget'. Use IF. | M1: Offered_Salary | N1: Expected_Salary | O1: (11)In Hiring sheet, create 'Salary_Negotiated' column: Yes if Offered_Salary ≠ Expected_Salary, else No. ( Salary_Negotiated) | Q1: Work_Hours | R1: (12)Flag attendance records where Work_Hours is blank. Use IF + ISBLANK. | T1: Attrition_Pct | U1: (13)In KPI sheet, create a column: If Attrition_Pct > 10 → 'High Attrition', else 'Normal'. Use IF. | W1: Employee_ID | X1: (14)Use IFERROR with VLOOKUP to fetch employee name from Employee_ID in Attendance sheet. Handle errors. | Z1: Employee_ID | AA1: (15)Extract the numeric part of Employee_ID (e.g., EMP0001 → 0001). Use MID or RIGHT. | AC1: Department | AD1: (16)Standardize the Department column — some values are lowercase. Use PROPER or UPPER. Create a helper column. | AF1: Full_Name | AG1: Department | AH1: Company | AI1: (17)Create a full label: 'Saurav Mohapatra | Engineering | TechNova Solutions'. Use CONCAT or &. | AK1: Full_Name | AL1: (18)Extract initials from employee Full_Name (e.g., Saurav Mohapatra → S.M.). Use LEFT + FIND + MID. | AN1: Source | AO1: (19)Standardize the 'Source' column in Hiring sheet (linkedin → LinkedIn, naukri → Naukri). Use IF + UPPER. | AQ1: Full_Name | AR1: (20)Find all employees whose surname is 'Mishra'. Use SEARCH or RIGHT in combination with IF. | AT1: Project_Name | AU1: (21)Count characters in Project_Name to identify unusually short names. Use LEN. | AW1: (22)Calculate tenure (in years) for each employee from their Joining_Date to today. Use DATEDIF. | AY1: Interview_Date | AZ1: Modified Interview date | BA1: (23)Extract Month and Year from Interview_Date in Hiring sheet. | BC1: Deadline | BD1: Modified Deadline | BE1: Status | BF1: (24)Find projects that are overdue: Deadline has passed but Status ≠ 'Completed'. Use TODAY() + IF. | BH1: Joining_Date | BI1: Modified Joining Date | BJ1: (25)Calculate working days each employee has been with the company. Use NETWORKDAYS. | BL1: (26)Find employees who joined in Q1 (Jan–Mar) of any year. Use MONTH() + IF. | BM1: Modified Interview date | BN1: Modified Joining Date | BO1: (27)Calculate the gap between Interview_Date and Joining_Date for placed candidates. Use DATEDIF. | BP1: Employee_ID | BQ1: Department | BR1: Employee_ID | BS1: Record_ID | BT1: (28)For each Attendance record, fetch the Employee's Department using VLOOKUP (from Employees sheet). | BV1: Employee_ID | BW1: Full_Name | BX1: Project_Name | BY1: Lead_Employee_ID | BZ1: (29)For each Project, fetch the Lead Employee's Name using XLOOKUP (from Employees sheet). | CB1: Full_Name (Hiring) | CC1: Full_Name (employees) | CD1: Designation | CE1: (31)Fetch the Designation of each employee who appears in the Hiring sheet as a candidate. | CG1: (32)Use XLOOKUP with IFERROR to find a Candidate by ID. Return 'Not Found' if not present.
F2: 4.5 | G2: {=_xlfn.IFS(F2>=4.5,"Excellent",AND(F2>=3.5,F2<=4.4),"Good",F2<3.5,"Needs Improvement")} -> Excellent | I2: 172.82 | J2: 149.22 | K2: =IF(J2>I2,"Over Budget","Within Budget") -> Within Budget | M2: 135000 | N2: 123018 | O2: =IF(M2<>N2,"Yes","No") -> Yes | Q2: 6.9 | R2: =IF(ISBLANK(Q2),"No","Yes") -> Yes | T2: 6.43 | U2: =IF(T2>10,"High Attrition","No") -> No | W2: EMP0076 | X2: =VLOOKUP(W2,Employees!$A$1:$B$601,2,FALSE) -> Bikash Biswal | Z2: EMP0001 | AA2: =RIGHT(Z2,4) -> 0001 | AC2: DevOps | AD2: =PROPER(AC2) -> Devops | AF2: Priyanka Jena | AG2: DevOps | AH2: CoastalDev Studio | AI2: =_xlfn.CONCAT(AF2,"|",AG2,"|",AH2) -> Priyanka Jena|DevOps|CoastalDev Studio | AK2: Priyanka Jena | AL2: =LEFT(AK2,1)&"."&MID(AK2,FIND(" ",AK2)+1,1)&"." -> P.J. | AN2: Job Portal | AO2: =IF(UPPER(AN2)="linkedin","Linkedln",IF(UPPER(AN2)="naukri","Naukri")) -> FALSE | AQ2: Priyanka Jena | AR2: =IF(ISNUMBER(SEARCH("Mishra",AQ2)),"Mishra","NO") -> NO | AT2: Supply Chain Optimizer | AU2: =LEN(AT2) -> 22 | AY2: 08-04-2024 | AZ2: =DATE(RIGHT(AY2,4),MID(AY2,4,2),LEFT(AY2,2)) -> 45390 | BA2: =MONTH(AZ2)&"-"&YEAR(AZ2) -> 4-2024 | BC2: 20-11-2022 | BD2: =DATE(RIGHT(BC2,4),MID(BC2,4,2),LEFT(BC2,2)) -> 44885 | BE2: Cancelled | BF2: =IF(AND(BD2<TODAY(),BE2<>"Completed"),"Overdue","On Track") -> Overdue | BM2: =DATE(RIGHT(AY2,4),MID(AY2,4,2),LEFT(AY2,2)) -> 45390 | BO2: =ABS(BN2-BM2) -> 45390 | BP2: EMP0001 | BQ2: DevOps | BR2: EMP0076 | BS2: ATT00001 | BT2: =VLOOKUP(BR2,$BP$2:$BQ$601,2,FALSE) -> Marketing | BV2: EMP0001 | BW2: Priyanka Jena | BX2: Supply Chain Optimizer | BY2: EMP0508 | BZ2: =VLOOKUP(BY2,$BV$2:$BW$601,2,FALSE) -> Barsha Pattnaik | CB2: Abhishek Ratha | CC2: Priyanka Jena | CD2: SRE | CE2: {=_xlfn.XLOOKUP(CB2:CB401,CC2:CC601,CD2:CD601,"Not Found",0)} -> Not Found | CG2: =IFERROR(_xlfn.XLOOKUP(Hiring!A2,Hiring!A2:A401,Hiring!B2:B401,,0),"Not Found") -> Abhishek Ratha
A3: SECTION A — AGGREGATE & CONDITIONAL FUNCTIONS | C3: Department | D3: Monthly Salary | F3: 1.5 | G3: {=_xlfn.IFS(F3>=4.5,"Excellent",AND(F3>=3.5,F3<=4.4),"Good",F3<3.5,"Needs Improvement")} -> Needs Improvement | I3: 123.83 | J3: 158.34 | K3: =IF(J3>I3,"Over Budget","Within Budget") -> Over Budget | M3: 132960 | N3: 139712 | O3: =IF(M3<>N3,"Yes","No") -> Yes | Q3: 7.78 | R3: =IF(ISBLANK(Q3),"No","Yes") -> Yes | T3: 24.1 | U3: =IF(T3>10,"High Attrition","No") -> High Attrition | W3: EMP0076 | X3: =VLOOKUP(W3,Employees!$A$1:$B$601,2,FALSE) -> Bikash Biswal | Z3: EMP0002 | AA3: =RIGHT(Z3,4) -> 0002 | AC3: Design | AD3: =PROPER(AC3) -> Design | AF3: Ranjit Samal | AG3: Design | AH3: InfySoft Bhubaneswar | AI3: =_xlfn.CONCAT(AF3,"|",AG3,"|",AH3) -> Ranjit Samal|Design|InfySoft Bhubaneswar | AK3: Ranjit Samal | AL3: =LEFT(AK3,1)&"."&MID(AK3,FIND(" ",AK3)+1,1)&"." -> R.S. | AN3: LinkedIn | AO3: =IF(UPPER(AN3)="linkedin","Linkedln",IF(UPPER(AN3)="naukri","Naukri")) -> Linkedln | AQ3: Ranjit Samal | AR3: =IF(ISNUMBER(SEARCH("Mishra",AQ3)),"Mishra","NO") -> NO | AT3: Supply Chain Optimizer | AU3: =LEN(AT3) -> 22 | AW3: =DATEDIF(BI3,TODAY(),"Y") -> 4 | AY3: 27-05-2024 | AZ3: =DATE(RIGHT(AY3,4),MID(AY3,4,2),LEFT(AY3,2)) -> 45439 | BA3: =MONTH(AZ3)&"-"&YEAR(AZ3) -> 5-2024 | BC3: 28-04-2024 | BD3: =DATE(RIGHT(BC3,4),MID(BC3,4,2),LEFT(BC3,2)) -> 45410 | BE3: Cancelled | BF3: =IF(AND(BD3<TODAY(),BE3<>"Completed"),"Overdue","On Track") -> Overdue | BH3: 05-03-2022 | BI3: =IF(LEN(LEFT(BH3,FIND("-",BH3)-1))=4,DATE(LEFT(BH3,4),MID(BH3,6,2),RIGHT(BH3,2)),DATE(RIGHT(BH3,4),MID(BH3,4,2),LEFT(BH3,2))) -> 44625 | BJ3: =NETWORKDAYS(BI3,TODAY()) -> 1160 | BL3: =IF(MONTH(BI3)<=3,"Q1","No") -> Q1 | BM3: =DATE(RIGHT(AY3,4),MID(AY3,4,2),LEFT(AY3,2)) -> 45439 | BN3: =IF(LEN(LEFT(BH3,FIND("-",BH3)-1))=4,DATE(LEFT(BH3,4),MID(BH3,6,2),RIGHT(BH3,2)),DATE(RIGHT(BH3,4),MID(BH3,4,2),LEFT(BH3,2))) -> 44625 | BO3: =ABS(BN3-BM3) -> 814 | BP3: EMP0002 | BQ3: Design | BR3: EMP0076 | BS3: ATT00002 | BT3: =VLOOKUP(BR3,$BP$2:$BQ$601,2,FALSE) -> Marketing | BV3: EMP0002 | BW3: Ranjit Samal | BX3: Supply Chain Optimizer | BY3: EMP0526 | BZ3: =VLOOKUP(BY3,$BV$2:$BW$601,2,FALSE) -> Ipsita Biswal | CB3: Bikash Behura | CC3: Ranjit Samal | CD3: UI Designer | CE3: Account Manager | CG3: =IFERROR(_xlfn.XLOOKUP(Hiring!A3,Hiring!A3:A402,Hiring!B3:B402,,0),"Not Found") -> Bikash Behura
A4: Q1 | B4: Calculate total monthly salary bill for each Department. Use SUMIF on Employees sheet. | C4: Engineering | D4: =SUMIFS(Employees!I:I,Employees!D:D,C4) -> 7253668 | F4: 3.4 | G4: {=_xlfn.IFS(F4>=4.5,"Excellent",AND(F4>=3.5,F4<=4.4),"Good",F4<3.5,"Needs Improvement")} -> Needs Improvement | I4: 110.56 | J4: 114.91 | K4: =IF(J4>I4,"Over Budget","Within Budget") -> Over Budget | M4: 28384 | N4: 26013 | O4: =IF(M4<>N4,"Yes","No") -> Yes | R4: =IF(ISBLANK(Q4),"No","Yes") -> No | T4: 8.33 | U4: =IF(T4>10,"High Attrition","No") -> No | W4: EMP0076 | X4: =VLOOKUP(W4,Employees!$A$1:$B$601,2,FALSE) -> Bikash Biswal | Z4: EMP0003 | AA4: =RIGHT(Z4,4) -> 0003 | AC4: DevOps | AD4: =PROPER(AC4) -> Devops | AF4: Subhasree Dhal | AG4: DevOps | AH4: NilGiri Digitals | AI4: =_xlfn.CONCAT(AF4,"|",AG4,"|",AH4) -> Subhasree Dhal|DevOps|NilGiri Digitals | AK4: Subhasree Dhal | AL4: =LEFT(AK4,1)&"."&MID(AK4,FIND(" ",AK4)+1,1)&"." -> S.D. | AN4: linkedin | AO4: =IF(UPPER(AN4)="linkedin","Linkedln",IF(UPPER(AN4)="naukri","Naukri")) -> Linkedln | AQ4: Subhasree Dhal | AR4: =IF(ISNUMBER(SEARCH("Mishra",AQ4)),"Mishra","NO") -> NO | AT4: Data Warehouse Migration | AU4: =LEN(AT4) -> 24 | AW4: =DATEDIF(BI4,TODAY(),"Y") -> 5 | AY4: 18-09-2024 | AZ4: =DATE(RIGHT(AY4,4),MID(AY4,4,2),LEFT(AY4,2)) -> 45553 | BA4: =MONTH(AZ4)&"-"&YEAR(AZ4) -> 9-2024 | BC4: 13-05-2022 | BD4: =DATE(RIGHT(BC4,4),MID(BC4,4,2),LEFT(BC4,2)) -> 44694 | BE4: Under Review | BF4: =IF(AND(BD4<TODAY(),BE4<>"Completed"),"Overdue","On Track") -> Overdue | BH4: 07-03-2021 | BI4: =IF(LEN(LEFT(BH4,FIND("-",BH4)-1))=4,DATE(LEFT(BH4,4),MID(BH4,6,2),RIGHT(BH4,2)),DATE(RIGHT(BH4,4),MID(BH4,4,2),LEFT(BH4,2))) -> 44262 | BJ4: =NETWORKDAYS(BI4,TODAY()) -> 1420 | BL4: =IF(MONTH(BI4)<=3,"Q1","No") -> Q1 | BM4: =DATE(RIGHT(AY4,4),MID(AY4,4,2),LEFT(AY4,2)) -> 45553 | BN4: =IF(LEN(LEFT(BH4,FIND("-",BH4)-1))=4,DATE(LEFT(BH4,4),MID(BH4,6,2),RIGHT(BH4,2)),DATE(RIGHT(BH4,4),MID(BH4,4,2),LEFT(BH4,2))) -> 44262 | BO4: =ABS(BN4-BM4) -> 1291 | BP4: EMP0003 | BQ4: DevOps | BR4: EMP0076 | BS4: ATT00003 | BT4: =VLOOKUP(BR4,$BP$2:$BQ$601,2,FALSE) -> Marketing | BV4: EMP0003 | BW4: Subhasree Dhal | BX4: Data Warehouse Migration | BY4: EMP0134 | BZ4: =VLOOKUP(BY4,$BV$2:$BW$601,2,FALSE) -> Nirmal Choudhury | CB4: Ankita Behura | CC4: Subhasree Dhal | CD4: SRE | CE4: Not Found | CG4: =IFERROR(_xlfn.XLOOKUP(Hiring!A4,Hiring!A4:A403,Hiring!B4:B403,,0),"Not Found") -> Ankita Behura
A5: Q2 | B5: Count how many employees have a Performance_Rating above 4.0. Use COUNTIF. | C5: =COUNTIF(Employees!L:L,">4.0") -> 160 | F5: 2.7 | G5: {=_xlfn.IFS(F5>=4.5,"Excellent",AND(F5>=3.5,F5<=4.4),"Good",F5<3.5,"Needs Improvement")} -> Needs Improvement | I5: 167.36 | J5: 156.31 | K5: =IF(J5>I5,"Over Budget","Within Budget") -> Within Budget | M5: 170600 | N5: 176914 | O5: =IF(M5<>N5,"Yes","No") -> Yes | Q5: 9.99 | R5: =IF(ISBLANK(Q5),"No","Yes") -> Yes | T5: 1.29 | U5: =IF(T5>10,"High Attrition","No") -> No | W5: EMP0076 | X5: =VLOOKUP(W5,Employees!$A$1:$B$601,2,FALSE) -> Bikash Biswal | Z5: EMP0004 | AA5: =RIGHT(Z5,4) -> 0004 | AC5: Engineering | AD5: =PROPER(AC5) -> Engineering | AF5: Bikash Jena | AG5: Engineering | AH5: CoastalDev Studio | AI5: =_xlfn.CONCAT(AF5,"|",AG5,"|",AH5) -> Bikash Jena|Engineering|CoastalDev Studio | AK5: Bikash Jena | AL5: =LEFT(AK5,1)&"."&MID(AK5,FIND(" ",AK5)+1,1)&"." -> B.J. | AN5: Campus | AO5: =IF(UPPER(AN5)="linkedin","Linkedln",IF(UPPER(AN5)="naukri","Naukri")) -> FALSE | AQ5: Bikash Jena | AR5: =IF(ISNUMBER(SEARCH("Mishra",AQ5)),"Mishra","NO") -> NO | AT5: IoT Gateway | AU5: =LEN(AT5) -> 11 | AW5: =DATEDIF(BI5,TODAY(),"Y") -> 5 | AY5: 11-12-2023 | AZ5: =DATE(RIGHT(AY5,4),MID(AY5,4,2),LEFT(AY5,2)) -> 45271 | BA5: =MONTH(AZ5)&"-"&YEAR(AZ5) -> 12-2023 | BC5: 03-11-2024 | BD5: =DATE(RIGHT(BC5,4),MID(BC5,4,2),LEFT(BC5,2)) -> 45599 | BE5: In Progress | BF5: =IF(AND(BD5<TODAY(),BE5<>"Completed"),"Overdue","On Track") -> Overdue | BH5: 21-03-2021 | BI5: =IF(LEN(LEFT(BH5,FIND("-",BH5)-1))=4,DATE(LEFT(BH5,4),MID(BH5,6,2),RIGHT(BH5,2)),DATE(RIGHT(BH5,4),MID(BH5,4,2),LEFT(BH5,2))) -> 44276 | BJ5: =NETWORKDAYS(BI5,TODAY()) -> 1410 | BL5: =IF(MONTH(BI5)<=3,"Q1","No") -> Q1 | BM5: =DATE(RIGHT(AY5,4),MID(AY5,4,2),LEFT(AY5,2)) -> 45271 | BN5: =IF(LEN(LEFT(BH5,FIND("-",BH5)-1))=4,DATE(LEFT(BH5,4),MID(BH5,6,2),RIGHT(BH5,2)),DATE(RIGHT(BH5,4),MID(BH5,4,2),LEFT(BH5,2))) -> 44276 | BO5: =ABS(BN5-BM5) -> 995 | BP5: EMP0004 | BQ5: Engineering | BR5: EMP0076 | BS5: ATT00004 | BT5: =VLOOKUP(BR5,$BP$2:$BQ$601,2,FALSE) -> Marketing | BV5: EMP0004 | BW5: Bikash Jena | BX5: IoT Gateway | BY5: EMP0530 | BZ5: =VLOOKUP(BY5,$BV$2:$BW$601,2,FALSE) -> Ankita Choudhury | CB5: Sudhansu Prusty | CC5: Bikash Jena | CD5: Tech Lead | CE5: CFO | CG5: =IFERROR(_xlfn.XLOOKUP(Hiring!A5,Hiring!A5:A404,Hiring!B5:B404,,0),"Not Found") -> Sudhansu Prusty
A6: Q3 | B6: Find the average Final Interview Score for candidates hired from 'LinkedIn'. Use AVERAGEIF on Hiring sheet. | C6: =AVERAGEIFS(Hiring!J:J,Hiring!G:G,"Linkedin") -> 6.4920455 | F6: 4.9 | G6: {=_xlfn.IFS(F6>=4.5,"Excellent",AND(F6>=3.5,F6<=4.4),"Good",F6<3.5,"Needs Improvement")} -> Excellent | I6: 111.58 | J6: 82.9 | K6: =IF(J6>I6,"Over Budget","Within Budget") -> Within Budget | M6: 164134 | N6: 155983 | O6: =IF(M6<>N6,"Yes","No") -> Yes | Q6: 10.75 | R6: =IF(ISBLANK(Q6),"No","Yes") -> Yes | T6: 12.17 | U6: =IF(T6>10,"High Attrition","No") -> High Attrition | W6: EMP0076 | X6: =VLOOKUP(W6,Employees!$A$1:$B$601,2,FALSE) -> Bikash Biswal | Z6: EMP0005 | AA6: =RIGHT(Z6,4) -> 0005 | AC6: Design | AD6: =PROPER(AC6) -> Design | AF6: Bikash Nanda | AG6: Design | AH6: SambalpurNet | AI6: =_xlfn.CONCAT(AF6,"|",AG6,"|",AH6) -> Bikash Nanda|Design|SambalpurNet | AK6: Bikash Nanda | AL6: =LEFT(AK6,1)&"."&MID(AK6,FIND(" ",AK6)+1,1)&"." -> B.N. | AN6: LinkedIn | AO6: =IF(UPPER(AN6)="linkedin","Linkedln",IF(UPPER(AN6)="naukri","Naukri")) -> Linkedln | AQ6: Bikash Nanda | AR6: =IF(ISNUMBER(SEARCH("Mishra",AQ6)),"Mishra","NO") -> NO | AT6: IoT Gateway | AU6: =LEN(AT6) -> 11 | AW6: =DATEDIF(BI6,TODAY(),"Y") -> 3 | AY6: 13-12-2024 | AZ6: =DATE(RIGHT(AY6,4),MID(AY6,4,2),LEFT(AY6,2)) -> 45639 | BA6: =MONTH(AZ6)&"-"&YEAR(AZ6) -> 12-2024 | BC6: 20-07-2023 | BD6: =DATE(RIGHT(BC6,4),MID(BC6,4,2),LEFT(BC6,2)) -> 45127 | BE6: Completed | BF6: =IF(AND(BD6<TODAY(),BE6<>"Completed"),"Overdue","On Track") -> On Track | BH6: 21-07-2023 | BI6: =IF(LEN(LEFT(BH6,FIND("-",BH6)-1))=4,DATE(LEFT(BH6,4),MID(BH6,6,2),RIGHT(BH6,2)),DATE(RIGHT(BH6,4),MID(BH6,4,2),LEFT(BH6,2))) -> 45128 | BJ6: =NETWORKDAYS(BI6,TODAY()) -> 801 | BL6: =IF(MONTH(BI6)<=3,"Q1","No") -> No | BM6: =DATE(RIGHT(AY6,4),MID(AY6,4,2),LEFT(AY6,2)) -> 45639 | BN6: =IF(LEN(LEFT(BH6,FIND("-",BH6)-1))=4,DATE(LEFT(BH6,4),MID(BH6,6,2),RIGHT(BH6,2)),DATE(RIGHT(BH6,4),MID(BH6,4,2),LEFT(BH6,2))) -> 45128 | BO6: =ABS(BN6-BM6) -> 511 | BP6: EMP0005 | BQ6: Design | BR6: EMP0076 | BS6: ATT00005 | BT6: =VLOOKUP(BR6,$BP$2:$BQ$601,2,FALSE) -> Marketing | BV6: EMP0005 | BW6: Bikash Nanda | BX6: IoT Gateway | BY6: EMP0214 | BZ6: =VLOOKUP(BY6,$BV$2:$BW$601,2,FALSE) -> Chinmaya Behura | CB6: Puspita Pattnaik | CC6: Bikash Nanda | CD6: Design Lead | CE6: Digital Marketer | CG6: =IFERROR(_xlfn.XLOOKUP(Hiring!A6,Hiring!A6:A405,Hiring!B6:B405,,0),"Not Found") -> Puspita Pattnaik
A7: Q4 | B7: Calculate total Billable Hours per Company using SUMIF on KPI sheet. | C7: Company | D7: Billable Hours_Total | F7: 2.9 | G7: {=_xlfn.IFS(F7>=4.5,"Excellent",AND(F7>=3.5,F7<=4.4),"Good",F7<3.5,"Needs Improvement")} -> Needs Improvement | I7: 167.64 | J7: 168.44 | K7: =IF(J7>I7,"Over Budget","Within Budget") -> Over Budget | M7: 39365 | N7: 37894 | O7: =IF(M7<>N7,"Yes","No") -> Yes | Q7: 7.23 | R7: =IF(ISBLANK(Q7),"No","Yes") -> Yes | T7: 4.31 | U7: =IF(T7>10,"High Attrition","No") -> No | W7: EMP0076 | X7: =VLOOKUP(W7,Employees!$A$1:$B$601,2,FALSE) -> Bikash Biswal | Z7: EMP0006 | AA7: =RIGHT(Z7,4) -> 0006 | AC7: Sales | AD7: =PROPER(AC7) -> Sales | AF7: Tapas Sahu | AG7: Sales | AH7: BlueLotus IT | AI7: =_xlfn.CONCAT(AF7,"|",AG7,"|",AH7) -> Tapas Sahu|Sales|BlueLotus IT | AK7: Tapas Sahu | AL7: =LEFT(AK7,1)&"."&MID(AK7,FIND(" ",AK7)+1,1)&"." -> T.S. | AN7: Walk-in | AO7: =IF(UPPER(AN7)="linkedin","Linkedln",IF(UPPER(AN7)="naukri","Naukri")) -> FALSE | AQ7: Tapas Sahu | AR7: =IF(ISNUMBER(SEARCH("Mishra",AQ7)),"Mishra","NO") -> NO | AT7: Smart Grid System | AU7: =LEN(AT7) -> 17 | AW7: =DATEDIF(BI7,TODAY(),"Y") -> 4 | AY7: 28-04-2023 | AZ7: =DATE(RIGHT(AY7,4),MID(AY7,4,2),LEFT(AY7,2)) -> 45044 | BA7: =MONTH(AZ7)&"-"&YEAR(AZ7) -> 4-2023 | BC7: 06-10-2021 | BD7: =DATE(RIGHT(BC7,4),MID(BC7,4,2),LEFT(BC7,2)) -> 44475 | BE7: In Progress | BF7: =IF(AND(BD7<TODAY(),BE7<>"Completed"),"Overdue","On Track") -> Overdue | BH7: 31-07-2022 | BI7: =IF(LEN(LEFT(BH7,FIND("-",BH7)-1))=4,DATE(LEFT(BH7,4),MID(BH7,6,2),RIGHT(BH7,2)),DATE(RIGHT(BH7,4),MID(BH7,4,2),LEFT(BH7,2))) -> 44773 | BJ7: =NETWORKDAYS(BI7,TODAY()) -> 1055 | BL7: =IF(MONTH(BI7)<=3,"Q1","No") -> No | BM7: =DATE(RIGHT(AY7,4),MID(AY7,4,2),LEFT(AY7,2)) -> 45044 | BN7: =IF(LEN(LEFT(BH7,FIND("-",BH7)-1))=4,DATE(LEFT(BH7,4),MID(BH7,6,2),RIGHT(BH7,2)),DATE(RIGHT(BH7,4),MID(BH7,4,2),LEFT(BH7,2))) -> 44773 | BO7: =ABS(BN7-BM7) -> 271 | BP7: EMP0006 | BQ7: Sales | BR7: EMP0076 | BS7: ATT00006 | BT7: =VLOOKUP(BR7,$BP$2:$BQ$601,2,FALSE) -> Marketing | BV7: EMP0006 | BW7: Tapas Sahu | BX7: Smart Grid System | BY7: EMP0161 | BZ7: =VLOOKUP(BY7,$BV$2:$BW$601,2,FALSE) -> Tapas Behura | CB7: Soumya Senapati | CC7: Tapas Sahu | CD7: Account Manager | CE7: Product Owner | CG7: =IFERROR(_xlfn.XLOOKUP(Hiring!A7,Hiring!A7:A406,Hiring!B7:B406,,0),"Not Found") -> Soumya Senapati
C8: InfySoft Bhubaneswar | D8: =SUMIFS(KPL_Summary!J4:J75,KPL_Summary!C4:C75,'All answers'!C8) -> 65260.4 | F8: 0 | G8: {=_xlfn.IFS(F8>=4.5,"Excellent",AND(F8>=3.5,F8<=4.4),"Good",F8<3.5,"Needs Improvement")} -> Needs Improvement | I8: 78.19 | J8: 69.7 | K8: =IF(J8>I8,"Over Budget","Within Budget") -> Within Budget | M8: 170751 | N8: 164283 | O8: =IF(M8<>N8,"Yes","No") -> Yes | Q8: 11.44 | R8: =IF(ISBLANK(Q8),"No","Yes") -> Yes | T8: 6.06 | U8: =IF(T8>10,"High Attrition","No") -> No | W8: EMP0076 | X8: =VLOOKUP(W8,Employees!$A$1:$B$601,2,FALSE) -> Bikash Biswal | Z8: EMP0007 | AA8: =RIGHT(Z8,4) -> 0007 | AC8: DevOps | AD8: =PROPER(AC8) -> Devops | AF8: Jyotirmayee Ratha | AG8: DevOps | AH8: SambalpurNet | AI8: =_xlfn.CONCAT(AF8,"|",AG8,"|",AH8) -> Jyotirmayee Ratha|DevOps|SambalpurNet | AK8: Jyotirmayee Ratha | AL8: =LEFT(AK8,1)&"."&MID(AK8,FIND(" ",AK8)+1,1)&"." -> J.R. | AN8: LinkedIn | AO8: =IF(UPPER(AN8)="linkedin","Linkedln",IF(UPPER(AN8)="naukri","Naukri")) -> Linkedln | AQ8: Jyotirmayee Ratha | AR8: =IF(ISNUMBER(SEARCH("Mishra",AQ8)),"Mishra","NO") -> NO | AT8: Fleet Management | AU8: =LEN(AT8) -> 16 | AW8: =DATEDIF(BI8,TODAY(),"Y") -> 7 | AY8: 01-02-2023 | AZ8: =DATE(RIGHT(AY8,4),MID(AY8,4,2),LEFT(AY8,2)) -> 44958 | BA8: =MONTH(AZ8)&"-"&YEAR(AZ8) -> 2-2023 | BC8: 10-11-2021 | BD8: =DATE(RIGHT(BC8,4),MID(BC8,4,2),LEFT(BC8,2)) -> 44510 | BE8: Under Review | BF8: =IF(AND(BD8<TODAY(),BE8<>"Completed"),"Overdue","On Track") -> Overdue | BH8: 28-12-2018 | BI8: =IF(LEN(LEFT(BH8,FIND("-",BH8)-1))=4,DATE(LEFT(BH8,4),MID(BH8,6,2),RIGHT(BH8,2)),DATE(RIGHT(BH8,4),MID(BH8,4,2),LEFT(BH8,2))) -> 43462 | BJ8: =NETWORKDAYS(BI8,TODAY()) -> 1991 | BL8: =IF(MONTH(BI8)<=3,"Q1","No") -> No | BM8: =DATE(RIGHT(AY8,4),MID(AY8,4,2),LEFT(AY8,2)) -> 44958 | BN8: =IF(LEN(LEFT(BH8,FIND("-",BH8)-1))=4,DATE(LEFT(BH8,4),MID(BH8,6,2),RIGHT(BH8,2)),DATE(RIGHT(BH8,4),MID(BH8,4,2),LEFT(BH8,2))) -> 43462 | BO8: =ABS(BN8-BM8) -> 1496 | BP8: EMP0007 | BQ8: DevOps | BR8: EMP0076 | BS8: ATT00007 | BT8: =VLOOKUP(BR8,$BP$2:$BQ$601,2,FALSE) -> Marketing | BV8: EMP0007 | BW8: Jyotirmayee Ratha | BX8: Fleet Management | BY8: EMP0105 | BZ8: =VLOOKUP(BY8,$BV$2:$BW$601,2,FALSE) -> Barsha Mahapatra | CB8: Satyajit Padhi | CC8: Jyotirmayee Ratha | CD8: SRE | CE8: Not Found | CG8: =IFERROR(_xlfn.XLOOKUP(Hiring!A8,Hiring!A8:A407,Hiring!B8:B407,,0),"Not Found") -> Satyajit Padhi
A9: Q5 | B9: Using SUMIFS, find total salary paid to 'Data Science' employees in 'Bhubaneswar' with salary > 50000. | C9: =SUMIFS(Employees!I:I,Employees!E:E,"Data Science",Employees!H:H,"Bhubaneswar",Employees!I:I,">50000") -> 3776916 | F9: 2.3 | G9: {=_xlfn.IFS(F9>=4.5,"Excellent",AND(F9>=3.5,F9<=4.4),"Good",F9<3.5,"Needs Improvement")} -> Needs Improvement | I9: 101.73 | J9: 115.49 | K9: =IF(J9>I9,"Over Budget","Within Budget") -> Over Budget | N9: 86255 | O9: =IF(M9<>N9,"Yes","No") -> Yes | Q9: 6.6 | R9: =IF(ISBLANK(Q9),"No","Yes") -> Yes | T9: 4.14 | U9: =IF(T9>10,"High Attrition","No") -> No | W9: EMP0076 | X9: =VLOOKUP(W9,Employees!$A$1:$B$601,2,FALSE) -> Bikash Biswal | Z9: EMP0008 | AA9: =RIGHT(Z9,4) -> 0008 | AC9: Product | AD9: =PROPER(AC9) -> Product | AF9: Tanmay Nanda | AG9: Product | AH9: TributeAI | AI9: =_xlfn.CONCAT(AF9,"|",AG9,"|",AH9) -> Tanmay Nanda|Product|TributeAI | AK9: Tanmay Nanda | AL9: =LEFT(AK9,1)&"."&MID(AK9,FIND(" ",AK9)+1,1)&"." -> T.N. | AN9: Job Portal | AO9: =IF(UPPER(AN9)="linkedin","Linkedln",IF(UPPER(AN9)="naukri","Naukri")) -> FALSE | AQ9: Tanmay Nanda | AR9: =IF(ISNUMBER(SEARCH("Mishra",AQ9)),"Mishra","NO") -> NO | AT9: Smart Grid System | AU9: =LEN(AT9) -> 17 | AW9: =DATEDIF(BI9,TODAY(),"Y") -> 3 | AY9: 23-09-2024 | AZ9: =DATE(RIGHT(AY9,4),MID(AY9,4,2),LEFT(AY9,2)) -> 45558 | BA9: =MONTH(AZ9)&"-"&YEAR(AZ9) -> 9-2024 | BC9: 08-04-2024 | BD9: =DATE(RIGHT(BC9,4),MID(BC9,4,2),LEFT(BC9,2)) -> 45390 | BE9: Under Review | BF9: =IF(AND(BD9<TODAY(),BE9<>"Completed"),"Overdue","On Track") -> Overdue | BH9: 2023-01-31 | BI9: =IF(LEN(LEFT(BH9,FIND("-",BH9)-1))=4,DATE(LEFT(BH9,4),MID(BH9,6,2),RIGHT(BH9,2)),DATE(RIGHT(BH9,4),MID(BH9,4,2),LEFT(BH9,2))) -> 44957 | BJ9: =NETWORKDAYS(BI9,TODAY()) -> 924 | BL9: =IF(MONTH(BI9)<=3,"Q1","No") -> Q1 | BM9: =DATE(RIGHT(AY9,4),MID(AY9,4,2),LEFT(AY9,2)) -> 45558 | BN9: =IF(LEN(LEFT(BH9,FIND("-",BH9)-1))=4,DATE(LEFT(BH9,4),MID(BH9,6,2),RIGHT(BH9,2)),DATE(RIGHT(BH9,4),MID(BH9,4,2),LEFT(BH9,2))) -> 44957 | BO9: =ABS(BN9-BM9) -> 601 | BP9: EMP0008 | BQ9: Product | BR9: EMP0076 | BS9: ATT00008 | BT9: =VLOOKUP(BR9,$BP$2:$BQ$601,2,FALSE) -> Marketing | BV9: EMP0008 | BW9: Tanmay Nanda | BX9: Smart Grid System | BY9: EMP0241 | BZ9: =VLOOKUP(BY9,$BV$2:$BW$601,2,FALSE) -> Tapas Parida | CB9: Sudhansu Biswal | CC9: Tanmay Nanda | CD9: Associate PM | CE9: BI Developer | CG9: =IFERROR(_xlfn.XLOOKUP(Hiring!A9,Hiring!A9:A408,Hiring!B9:B408,,0),"Not Found") -> Sudhansu Biswal
