Workbook

Sheet Branches
A1: Branch_ID | B1: Branch_Name | C1: Manager | D1: Region | E1: State | F1: Target_Revenue_Lakhs | G1: Established_Year
A2: BR001 | B2: Bhubaneswar Main | C2: Rajesh Kumar | D2: North | E2: Jharkhand | F2: 209.86 | G2: 2012
A3: BR002 | B3: Cuttack Central | C3: Priya Mohanty | D3: North | E3: Chhattisgarh | F3: 105.8 | G3: 2007
A4: BR003 | B4: Rourkela Industrial | C4: Suresh Panda | D4: North | E4: Odisha | F4: 197.62 | G4: 2007
A5: BR004 | B5: Puri Tourism | C5: Anita Das | D5: Central | E5: Chhattisgarh | F5: 104.66 | G5: 2005
A6: BR005 | B6: Sambalpur Regional | C6: Bikash Nayak | D6: Central | E6: Andhra Pradesh | F6: 190.31 | G6: 2012
A7: BR006 | B7: Berhampur South | C7: Sunita Sahu | D7: East | E7: Odisha | F7: 162.3 | G7: 2010
A8: BR007 | B8: Balasore North | C8: Ramesh Behera | D8: East | E8: Jharkhand | F8: 224.53 | G8: 2009
A9: BR008 | B9: Angul Mining | C9: Kavita Rath | D9: East | E9: Odisha | F9: 103.83 | G9: 2007
A10: BR009 | B10: Jharsuguda Energy | C10: Deepak Mishra | D10: East | E10: Jharkhand | F10: 144.98 | G10: 2013
A11: BR010 | B11: Dhenkanal Rural | C11: Pooja Tripathi | D11: West | E11: Chhattisgarh | F11: 251.78 | G11: 2008

Sheet Customers
A1: Customer_ID | B1: Name | C1: Gender | D1: City | E1: Occupation | F1: Annual_Income_Lakhs | G1: Credit_Score | H1: Joining_Date | I1: Age | J1: Loan_History_Count
A2: CUST0001 | B2: Mira Pradhan | C2: Male | D2: Dhenkanal | E2: retired | F2: 43.5 | G2: 585 | H2: 22-07-2020 | I2: 40 | J2: 0
A3: CUST0002 | B3: Sita Rath | C3: Male | D3: Balasore | E3: Government Employee | F3: 20.15 | G3: 657 | H3: 20-10-2018 | I3: 60 | J3: 5
A4: CUST0003 | B4: Kavita Rout | C4: female | D4: Sambalpur | E4: Government Employee | F4: 49.51 | G4: 835 | H4: 21-08-2021 | I4: 25 | J4: 1
A5: CUST0004 | B5: Ashok Mohanty | C5: M | D5: Balasore | E5: Salaried | F5: 47.32 | G5: 711 | H5: 07-08-2023 | I5: 47 | J5: 5
A6: CUST0005 | B6: Arjun Nayak | C6: M | D6: Rourkela | E6: retired | F6: 15.35 | G6: 848 | H6: 17-06-2020 | I6: 30 | J6: 4
A7: CUST0006 | B7: Nisha Das | C7: Male | D7: Cuttack | E7: retired | F7: 34.98 | G7: 747 | H7: 02-04-2023 | I7: 55 | J7: 2
A8: CUST0007 | B8: Seema Kumar | C8: female | D8: Cuttack | E8: retired | F8: 38.29 | G8: 724 | H8: 16-11-2022 | I8: 32 | J8: 3
A9: CUST0008 | B9: Amit Mishra | C9: male | D9: Rourkela | E9: Salaried | F9: 17.03 | G9: 861 | H9: 12-03-2022 | I9: 32 | J9: 4
A10: CUST0009 | B10: Prakash Swain | C10: Male | D10: Jharsuguda | E10: Government Employee | G10: 707 | H10: 13-09-2020 | I10: 58 | J10: 0
A11: CUST0010 | B11: Ravi Dash | C11: Male | D11: Dhenkanal | E11: Self-Employed | F11: 47.5 | G11: 820 | H11: 30-09-2022 | I11: 35 | J11: 4
A12: CUST0011 | B12: Prakash Behera | C12: female | D12: Berhampur | E12: retired | F12: 23.59 | G12: 611 | H12: 20-09-2018 | I12: 43 | J12: 0
A13: CUST0012 | B13: Vijay Rout | C13: Female | D13: Jharsuguda | E13: Salaried | F13: 32.66 | G13: 566 | H13: 18-10-2018 | I13: 54 | J13: 1
A14: CUST0013 | B14: Bikash Dash | C14: Female | D14: Dhenkanal | E14: retired | F14: 29.84 | G14: 792 | H14: 19-02-2020 | I14: 28 | J14: 0
A15: CUST0014 | B15: Rekha Patnaik | C15: M | D15: Balasore | E15: Government Employee | F15: 5.55 | G15: 880 | H15: 08-07-2022 | I15: 43 | J15: 0
A16: CUST0015 | B16: Anita Behera | C16: Female | D16: Dhenkanal | E16: Self-Employed | F16: 16.09 | G16: 588 | H16: 04-03-2024 | I16: 28 | J16: 0
A17: CUST0016 | B17: Manoj Rout | C17: Male | D17: Cuttack | E17: Self-Employed | F17: 25.62 | G17: 580 | H17: 09-01-2018 | I17: 46 | J17: 2
A18: CUST0017 | B18: Mira Sethi | C18: M | D18: Balasore | E18: retired | F18: 10.28 | G18: 579 | H18: 30-01-2024 | I18: 25 | J18: 5
A19: CUST0018 | B19: Deepak Mohanty | C19: Male | D19: Jharsuguda | E19: Freelancer | F19: 27.96 | G19: 810 | H19: 01-02-2020 | I19: 26 | J19: 4
A20: CUST0019 | B20: Ravi Rath | C20: F | D20: Cuttack | E20: Self-Employed | F20: 4.87 | G20: 886 | H20: 12-11-2023 | I20: 42 | J20: 2
A21: CUST0020 | B21: Suresh Sahoo | C21: Female | D21: Berhampur | E21: Self-Employed | F21: 17.1 | G21: 587 | H21: 2024/12/19 | I21: 58 | J21: 0
A22: CUST0021 | B22: Ravi Rout | C22: Female | D22: Dhenkanal | E22: Self-Employed | F22: 44.4 | G22: 739 | H22: 30-11-2022 | I22: 56 | J22: 5
... A24: CUST0023 | B24: Bikash Tripathi | C24: male | D24: Sambalpur | E24: Self-Employed | F24: 43.09 | G24: 678 | H24: 28-07-2018 | I24: 27 | J24: 5
A25: CUST0024 | B25: Lata Mishra | D25: Bhubaneswar | E25: Self-Employed | F25: 15.31 | G25: 832 | H25: 16-04-2024 | I25: 22 | J25: 0
A26: CUST0025 | B26: Ravi Nayak | C26: male | D26: Bhubaneswar | E26: Freelancer | F26: 23.2 | H26: 13-06-2018 | I26: 44 | J26: 1
A27: CUST0026 | B27: Rekha Rath | C27: female | D27: Cuttack | E27: Freelancer | F27: 22.1 | G27: 629 | H27: 27-08-2020 | I27: 32 | J27: 1
A28: CUST0027 | B28: Dilip Patnaik | C28: Male | D28: Rourkela | E28: Government Employee | F28: 43.61 | G28: 686 | H28: 19-03-2019 | I28: 46 | J28: 0
A29: CUST0028 | B29: Sita Dash | C29: Female | D29: Sambalpur | E29: Business Owner | F29: 40.38 | G29: 562 | H29: 21-06-2022 | I29: 43 | J29: 2
A30: CUST0029 | B30: Sita Das | C30: M | D30: Puri | E30: Government Employee | F30: 42.65 | G30: 564 | H30: 05-12-2020 | I30: 33 | J30: 4
A31: CUST0030 | B31: Bikash Mohanty | C31: Male | D31: Jharsuguda | E31: Business Owner | F31: 17.74 | G31: 811 | H31: 19-06-2024 | I31: 34 | J31: 2
A32: CUST0031 | B32: Priya Patnaik | C32: Male | D32: Dhenkanal | E32: retired | F32: 37.87 | G32: 736 | H32: 14-09-2021 | I32: 61 | J32: 2
A33: CUST0032 | B33: Rekha Panda | C33: female | D33: Berhampur | E33: Business Owner | F33: 18.33 | G33: 833 | H33: 19-09-2022 | I33: 64 | J33: 3
A34: CUST0033 | B34: Rekha Sahu | C34: male | D34: Jharsuguda | E34: Government Employee | F34: 3.02 | G34: 770 | H34: 20-10-2024 | I34: 63 | J34: 2
A35: CUST0034 | B35: Arjun Sethi | C35: F | D35: Bhubaneswar | E35: Freelancer | F35: 45.36 | G35: 636 | H35: 08-03-2021 | I35: 54 | J35: 5
A36: CUST0035 | B36: Manoj Barik | C36: M | D36: Cuttack | E36: retired | F36: 40.91 | G36: 573 | H36: 01-05-2023 | I36: 61 | J36: 0
A37: CUST0036 | B37: Arjun Patnaik | C37: female | D37: Jharsuguda | E37: retired | F37: 26.24 | G37: 885 | H37: 13-03-2019 | I37: 49 | J37: 1
A38: CUST0037 | B38: Kavita Swain | C38: F | D38: Bhubaneswar | E38: Self-Employed | F38: 8.7 | G38: 787 | H38: 08-04-2024 | I38: 60 | J38: 2
... A45: CUST0044 | B45: Bikash Pradhan | C45: M | D45: Sambalpur | E45: Business Owner | F45: 44.34 | G45: 765 | H45: 02-12-2018 | I45: 52 | J45: 0
A46: CUST0045 | B46: Mamata Rout | C46: Male | D46: Puri | E46: retired | F46: 47.99 | H46: 09-10-2020 | I46: 34 | J46: 0
A47: CUST0046 | B47: Puja Nayak | C47: Female | D47: Rourkela | E47: retired | F47: 47.54 | G47: 681 | H47: 19-11-2019 | I47: 60 | J47: 4
...

Sheet Sheet3
A1: Customer_ID | B1: Name | C1: Gender | D1: City | E1: Occupation | F1: Annual_Income_Lakhs | G1: Credit_Score | H1: Joining_Date | I1: Age | J1: Loan_History_Count | K1: Loan_Amount_Lakhs
A2: CUST0001 | B2: Mira Pradhan | C2: Male | D2: Dhenkanal | E2: retired | F2: 43.5 | G2: 585 | H2: 22-07-2020 | I2: 40 | J2: 0 | K2: 73.8
A3: CUST0002 | B3: Sita Rath | C3: Male | D3: Balasore | E3: Government Employee | F3: 20.15 | G3: 657 | H3: 20-10-2018 | I3: 60 | J3: 5 | K3: 47.65
A4: CUST0003 | B4: Kavita Rout | C4: female | D4: Sambalpur | E4: Government Employee | F4: 49.51 | G4: 835 | H4: 21-08-2021 | I4: 25 | J4: 1 | K4: 58.02
A5: CUST0004 | B5: Ashok Mohanty | C5: M | D5: Balasore | E5: Salaried | F5: 47.32 | G5: 711 | H5: 07-08-2023 | I5: 47 | J5: 5 | K5: 25.12
A6: CUST0005 | B6: Arjun Nayak | C6: M | D6: Rourkela | E6: retired | F6: 15.35 | G6: 848 | H6: 17-06-2020 | I6: 30 | J6: 4 | K6: 80.93
A7: CUST0006 | B7: Nisha Das | C7: Male | D7: Cuttack | E7: retired | F7: 34.98 | G7: 747 | H7: 02-04-2023 | I7: 55 | J7: 2 | K7: 82.82
A8: CUST0007 | B8: Seema Kumar | C8: female | D8: Cuttack | E8: retired | F8: 38.29 | G8: 724 | H8: 16-11-2022 | I8: 32 | J8: 3 | K8: 66.27
A9: CUST0008 | B9: Amit Mishra | C9: male | D9: Rourkela | E9: Salaried | F9: 17.03 | G9: 861 | H9: 12-03-2022 | I9: 32 | J9: 4 | K9: 62.07
A10: CUST0009 | B10: Prakash Swain | C10: Male | D10: Jharsuguda | E10: Government Employee | G10: 707 | H10: 13-09-2020 | I10: 58 | J10: 0 | K10: 33.27
A11: CUST0010 | B11: Ravi Dash | C11: Male | D11: Dhenkanal | E11: Self-Employed | F11: 47.5 | G11: 820 | H11: 30-09-2022 | I11: 35 | J11: 4 | K11: 48.96
A12: CUST0011 | B12: Prakash Behera | C12: female | D12: Berhampur | E12: retired | F12: 23.59 | G12: 611 | H12: 20-09-2018 | I12: 43 | J12: 0 | K12: 69.53
A13: CUST0012 | B13: Vijay Rout | C13: Female | D13: Jharsuguda | E13: Salaried | F13: 32.66 | G13: 566 | H13: 18-10-2018 | I13: 54 | J13: 1 | K13: 85.65
A14: CUST0013 | B14: Bikash Dash | C14: Female | D14: Dhenkanal | E14: retired | F14: 29.84 | G14: 792 | H14: 19-02-2020 | I14: 28 | J14: 0 | K14: 89.29
A15: CUST0014 | B15: Rekha Patnaik | C15: M | D15: Balasore | E15: Government Employee | F15: 5.55 | G15: 880 | H15: 08-07-2022 | I15: 43 | J15: 0 | K15: 24.81
A16: CUST0015 | B16: Anita Behera | C16: Female | D16: Dhenkanal | E16: Self-Employed | F16: 16.09 | G16: 588 | H16: 04-03-2024 | I16: 28 | J16: 0 | K16: 85.93
A17: CUST0016 | B17: Manoj Rout | C17: Male | D17: Cuttack | E17: Self-Employed | F17: 25.62 | G17: 580 | H17: 09-01-2018 | I17: 46 | J17: 2 | K17: 53.56
A18: CUST0017 | B18: Mira Sethi | C18: M | D18: Balasore | E18: retired | F18: 10.28 | G18: 579 | H18: 30-01-2024 | I18: 25 | J18: 5 | K18: 37.19
A19: CUST0018 | B19: Deepak Mohanty | C19: Male | D19: Jharsuguda | E19: Freelancer | F19: 27.96 | G19: 810 | H19: 01-02-2020 | I19: 26 | J19: 4 | K19: 75.56
A20: CUST0019 | B20: Ravi Rath | C20: F | D20: Cuttack | E20: Self-Employed | F20: 4.87 | G20: 886 | H20: 12-11-2023 | I20: 42 | J20: 2 | K20: 68.15
A21: CUST0020 | B21: Suresh Sahoo | C21: Female | D21: Berhampur | E21: Self-Employed | F21: 17.1 | G21: 587 | H21: 2024/12/19 | I21: 58 | J21: 0 | K21: 70.01
A22: CUST0021 | B22: Ravi Rout | C22: Female | D22: Dhenkanal | E22: Self-Employed | F22: 44.4 | G22: 739 | H22: 30-11-2022 | I22: 56 | J22: 5 | K22: 83.66
... A25: CUST0024 | B25: Lata Mishra | C25: Male | D25: Bhubaneswar | E25: Self-Employed | F25: 15.31 | G25: 832 | H25: 16-04-2024 | I25: 22 | J25: 0 | K25: 13.03
A26: CUST0025 | B26: Ravi Nayak | C26: male | D26: Bhubaneswar | E26: Freelancer | F26: 23.2 | H26: 13-06-2018 | I26: 44 | J26: 1 | K26: 67.02
A27: CUST0026 | B27: Rekha Rath | C27: female | D27: Cuttack | E27: Freelancer | F27: 22.1 | G27: 629 | H27: 27-08-2020 | I27: 32 | J27: 1 | K27: 62.13
A28: CUST0027 | B28: Dilip Patnaik | C28: Male | D28: Rourkela | E28: Government Employee | F28: 43.61 | G28: 686 | H28: 19-03-2019 | I28: 46 | J28: 0 | K28: 20.25
A29: CUST0028 | B29: Sita Dash | C29: Female | D29: Sambalpur | E29: Business Owner | F29: 40.38 | G29: 562 | H29: 21-06-2022 | I29: 43 | J29: 2 | K29: 22.35
A30: CUST0029 | B30: Sita Das | C30: M | D30: Puri | E30: Government Employee | F30: 42.65 | G30: 564 | H30: 05-12-2020 | I30: 33 | J30: 4 | K30: 47.99
A31: CUST0030 | B31: Bikash Mohanty | C31: Male | D31: Jharsuguda | E31: Business Owner | F31: 17.74 | G31: 811 | H31: 19-06-2024 | I31: 34 | J31: 2 | K31: 19.41
A32: CUST0031 | B32: Priya Patnaik | C32: Male | D32: Dhenkanal | E32: retired | F32: 37.87 | G32: 736 | H32: 14-09-2021 | I32: 61 | J32: 2 | K32: 83.59
A33: CUST0032 | B33: Rekha Panda | C33: female | D33: Berhampur | E33: Business Owner | F33: 18.33 | G33: 833 | H33: 19-09-2022 | I33: 64 | J33: 3 | K33: 56.99
A34: CUST0033 | B34: Rekha Sahu | C34: male | D34: Jharsuguda | E34: Government Employee | F34: 3.02 | G34: 770 | H34: 20-10-2024 | I34: 63 | J34: 2 | K34: 27.99
A35: CUST0034 | B35: Arjun Sethi | C35: F | D35: Bhubaneswar | E35: Freelancer | F35: 45.36 | G35: 636 | H35: 08-03-2021 | I35: 54 | J35: 5 | K35: 82.86
A36: CUST0035 | B36: Manoj Barik | C36: M | D36: Cuttack | E36: retired | F36: 40.91 | G36: 573 | H36: 01-05-2023 | I36: 61 | J36: 0 | K36: 92.17
A37: CUST0036 | B37: Arjun Patnaik | C37: female | D37: Jharsuguda | E37: retired | F37: 26.24 | G37: 885 | H37: 13-03-2019 | I37: 49 | J37: 1 | K37: 82.07
A38: CUST0037 | B38: Kavita Swain | C38: F | D38: Bhubaneswar | E38: Self-Employed | F38: 8.7 | G38: 787 | H38: 08-04-2024 | I38: 60 | J38: 2 | K38: 15.09
... A45: CUST0044 | B45: Bikash Pradhan | C45: M | D45: Sambalpur | E45: Business Owner | F45: 44.34 | G45: 765 | H45: 02-12-2018 | I45: 52 | J45: 0 | K45: 40.09
A46: CUST0045 | B46: Mamata Rout | C46: Male | D46: Puri | E46: retired | F46: 47.99 | H46: 09-10-2020 | I46: 34 | J46: 0 | K46: 50.41
A47: CUST0046 | B47: Puja Nayak | C47: Female | D47: Rourkela | E47: retired | F47: 47.54 | G47: 681 | H47: 19-11-2019 | I47: 60 | J47: 4 | K47: 63.21
A48: CUST0047 | B48: Mamata Panda | C48: Female | D48: Berhampur | E48: Freelancer | G48: 896 | H48: 18-03-2022 | I48: 47 | J48: 5 | K48: 76.26
...

Sheet Sheet21
A1: Payment_Status | B1: Defaulted
A3: Region | B3: Count of Transaction_ID
A4: Central | B4: 76
A5: East | B5: 67
A6: North | B6: 75
A7: South | B7: 72
A8: West | B8: 69
A9: Grand Total | B9: 359

Sheet Transitions
A1: Transaction_ID | B1: Customer_ID | C1: Branch_ID | D1: Region | E1: Product | F1: Loan_Type | G1: Loan_Amount_Lakhs | H1: Interest_Rate_Pct | I1: Processing_Fee_Lakhs | J1: EMI_Monthly | K1: Payment_Status | L1: Credit_Score | M1: Approval_Status | O1: Transaction_Date | P1: Transaction_Date | Q1: Disbursal_Date | R1: Tenure_Months | S1: Outstanding_Balance
A2: TXN00001 | B2: CUST0184 | C2: BR008 | D2: North | E2: Business Loan | F2: Unsecured | G2: 73.8 | H2: 9.62 | I2: 1.1658 | J2: 1.8583 | K2: Partially Paid | L2: 557 | M2: approved | N2: =PROPER(M2) -> Approved | O2: 10-05-2022 | P2: 10-05-2022 | Q2: 23-05-2022 | R2: 48 | S2: 41.29
A3: TXN00002 | B3: CUST0428 | C3: BR008 | D3: North | E3: Home Loan | F3: Unsecured | G3: 6.55 | H3: 7.97 | I3: 0.0444 | J3: 0.0547 | K3: Partially Paid | L3: 600 | M3: Rejected | N3: =PROPER(M3) -> Rejected | O3: 02-11-2022 | P3: 02-11-2022 | R3: 240 | S3: 4.78
A4: TXN00003 | B4: CUST0377 | C4: BR003 | D4: West | E4: Business Loan | F4: Secured | G4: 47.65 | H4: 8 | I4: 0.7395 | J4: 1.4932 | K4: Paid | L4: 690 | M4: Rejected | N4: =PROPER(M4) -> Rejected | O4: 13-04-2022 | P4: 13-04-2022 | R4: 36 | S4: 0
A5: TXN00004 | B5: CUST0050 | C5: BR008 | D5: Central | E5: Personal Loan | F5: Semi-Secured | G5: 7.33 | H5: 8.76 | I5: 0.1021 | J5: 0.1816 | K5: Paid | L5: 797 | M5: Rejected | N5: =PROPER(M5) -> Rejected | O5: 22-05-2024 | P5: 22-05-2024 | R5: 48 | S5: 0
A6: TXN00005 | B6: CUST0378 | C6: BR007 | D6: East | E6: Home Loan | F6: Semi-Secured | G6: 58.02 | H6: 16.7 | I6: 0.9803 | J6: 5.2834 | K6: Defaulted | L6: 751 | M6: Rejected | N6: =PROPER(M6) -> Rejected | O6: 19-11-2023 | P6: 19-11-2023 | R6: 12 | S6: 8.92
A7: TXN00006 | B7: CUST0087 | C7: BR006 | D7: Central | E7: Personal Loan | F7: Unsecured | G7: 25.12 | H7: 8.97 | I7: 0.4237 | J7: 0.3178 | K7: Pending | L7: 748 | M7: Approved | N7: =PROPER(M7) -> Approved | O7: 24-09-2024 | P7: 24-09-2024 | Q7: 26-09-2024 | R7: 120 | S7: 2.65
A8: TXN00007 | B8: CUST0334 | C8: BR010 | D8: East | E8: Education Loan | F8: Semi-Secured | G8: 80.93 | H8: 15.12 | I8: 0.6549 | J8: 1.9304 | K8: Defaulted | L8: 866 | M8: approved | N8: =PROPER(M8) -> Approved | O8: 23-04-2024 | P8: 23-04-2024 | Q8: 27-04-2024 | R8: 60 | S8: 72.62
A9: TXN00008 | B9: CUST0093 | C9: BR008 | D9: Central | E9: Home Loan | F9: Semi-Secured | G9: 82.82 | H9: 12.11 | I9: 1.1069 | J9: 2.1854 | K9: Paid | L9: 887 | M9: APPROVED | N9: =PROPER(M9) -> Approved | O9: 15-07-2022 | P9: 15-07-2022 | Q9: 25-07-2022 | R9: 48 | S9: 0
A10: TXN00009 | B10: CUST0277 | C10: BR009 | D10: South | E10: Education Loan | F10: Semi-Secured | G10: 66.27 | H10: 9.63 | I10: 1.1232 | J10: 0.6972 | K10: Partially Paid | L10: 793 | M10: Rejected | N10: =PROPER(M10) -> Rejected | O10: 24-11-2022 | P10: 24-11-2022 | R10: 180 | S10: 44.38
A11: TXN00010 | B11: CUST0146 | C11: BR004 | D11: West | E11: Auto Loan | F11: Unsecured | G11: 62.07 | H11: 12.48 | I11: 0.4076 | J11: 5.5288 | K11: Defaulted | L11: 713 | M11: Rejected | N11: =PROPER(M11) -> Rejected | O11: 20-11-2022 | P11: 20-11-2022 | R11: 12 | S11: 47.65
A12: TXN00011 | B12: CUST0459 | C12: BR004 | D12: West | E12: Gold Loan | F12: Semi-Secured | G12: 33.27 | H12: 14.95 | I12: 0.3289 | J12: 1.6124 | K12: Overdue | L12: 639 | M12: Rejected | N12: =PROPER(M12) -> Rejected | O12: 20-07-2022 | P12: 20-07-2022 | R12: 24 | S12: 10.03
A13: TXN00012 | B13: CUST0457 | C13: BR004 | D13: North | E13: Education Loan | F13: Semi-Secured | G13: 48.96 | H13: 9.09 | I13: 0.9262 | J13: 0.4992 | K13: Pending | L13: 731 | M13: approved | N13: =PROPER(M13) -> Approved | O13: 04-02-2024 | P13: 04-02-2024 | Q13: 07-02-2024 | R13: 180 | S13: 23.95
A14: TXN00013 | B14: CUST0139 | C14: BR004 | D14: East | E14: Personal Loan | F14: Secured | G14: 69.53 | H14: 9 | I14: 1.2359 | J14: 0.7052 | K14: Partially Paid | L14: 738 | M14: Rejected | N14: =PROPER(M14) -> Rejected | O14: 05-12-2023 | P14: 05-12-2023 | R14: 180 | S14: 19.95
A15: TXN00014 | B15: CUST0407 | C15: BR010 | D15: South | E15: Gold Loan | F15: Semi-Secured | G15: 85.65 | H15: 16.93 | I15: 1.0568 | J15: 2.4683 | K15: Defaulted | L15: 863 | M15: approved | N15: =PROPER(M15) -> Approved | O15: 05-08-2024 | P15: 05-08-2024 | Q15: 10-08-2024 | R15: 48 | S15: 9.62
A16: TXN00015 | B16: CUST0127 | C16: BR006 | D16: West | E16: Gold Loan | F16: Secured | G16: 89.29 | H16: 9.14 | I16: 1.2148 | J16: 7.8143 | K16: Partially Paid | L16: 560 | M16: Approved | N16: =PROPER(M16) -> Approved | O16: 24-03-2022 | P16: 24-03-2022 | Q16: 01-04-2022 | R16: 12 | S16: 64.6
A17: TXN00016 | B17: CUST0202 | C17: BR008 | D17: North | E17: Education Loan | F17: Unsecured | G17: 24.81 | H17: 7.64 | I17: 0.3964 | J17: 0.6015 | L17: 582 | M17: Under Review | N17: =PROPER(M17) -> Under Review | O17: 29-08-2023 | P17: 29-08-2023 | R17: 48 | S17: 7.52
A18: TXN00017 | B18: CUST0343 | C18: BR005 | D18: South | E18: Business Loan | F18: Unsecured | G18: 85.93 | H18: 7.77 | I18: 1.0159 | J18: 2.6836 | L18: 649 | M18: Rejected | N18: =PROPER(M18) -> Rejected | O18: 29-01-2024 | P18: 29-01-2024 | R18: 36 | S18: 54.38
A19: TXN00018 | B19: CUST0322 | C19: BR002 | D19: West | E19: Business Loan | F19: Unsecured | G19: 53.56 | H19: 15.78 | I19: 0.8286 | J19: 0.7363 | K19: Defaulted | L19: 849 | M19: Rejected | N19: =PROPER(M19) -> Rejected | O19: 15-06-2022 | P19: 15-06-2022 | R19: 240 | S19: 33.6
A20: TXN00019 | B20: CUST0264 | C20: BR006 | D20: North | E20: Home Loan | F20: Unsecured | G20: 37.19 | H20: 11.52 | I20: 0.2837 | J20: 0.3971 | K20: Paid | L20: 580 | M20: APPROVED | N20: =PROPER(M20) -> Approved | O20: 24-02-2023 | P20: 24-02-2023 | Q20: 27-02-2023 | R20: 240 | S20: 0
A21: TXN00020 | B21: CUST0059 | C21: BR008 | D21: Central | E21: Business Loan | F21: Secured | G21: 75.56 | H21: 11.03 | I21: 1.3955 | J21: 0.7815 | K21: Partially Paid | L21: 702 | M21: Under Review | N21: =PROPER(M21) -> Under Review | O21: 22-04-2022 | P21: 22-04-2022 | R21: 240 | S21: 11.63
A22: TXN00021 | B22: CUST0270 | C22: BR002 | D22: West | E22: Business Loan | F22: Semi-Secured | G22: 68.15 | H22: 10.71 | I22: 0.9755 | J22: 3.1672 | K22: Pending | L22: 845 | M22: approved | N22: =PROPER(M22) -> Approved | O22: 28-06-2022 | P22: 28-06-2022 | Q22: 30-06-2022 | R22: 24 | S22: 29.45
A23: TXN00022 | B23: CUST0040 | C23: BR002 | D23: South | E23: Auto Loan | F23: Secured | G23: 70.01 | H23: 17.12 | I23: 0.8969 | J23: 6.3892 | K23: Overdue | L23: 788 | M23: approved | N23: =PROPER(M23) -> Approved | O23: 28-09-2022 | P23: 28-09-2022 | Q23: 06-10-2022 | R23: 12 | S23: 27.63
A24: TXN00023 | B24: CUST0150 | C24: BR004 | D24: North | E24: Home Loan | F24: Secured | G24: 83.66 | H24: 11.19 | I24: 1.1445 | J24: 1.4408 | K24: Partially Paid | L24: 853 | M24: Rejected | N24: =PROPER(M24) -> Rejected | O24: 21-12-2024 | P24: 21-12-2024 | R24: 84 | S24: 68.23
A25: TXN00024 | B25: CUST0068 | C25: BR005 | D25: South | E25: Auto Loan | F25: Secured | G25: 48.94 | H25: 15.97 | I25: 0.2794 | J25: 0.9712 | K25: Overdue | L25: 617 | M25: approved | N25: =PROPER(M25) -> Approved | O25: 07-12-2022 | P25: 07-12-2022 | Q25: 17-12-2022 | R25: 84 | S25: 43.34
A26: TXN00025 | B26: CUST0499 | C26: BR003 | D26: South | E26: Personal Loan | F26: Secured | G26: 12.57 | H26: 13.82 | I26: 0.146 | J26: 0.2343 | K26: Pending | L26: 881 | M26: Rejected | N26: =PROPER(M26) -> Rejected | O26: 13-03-2022 | P26: 13-03-2022 | R26: 84 | S26: 8.37
A27: TXN00026 | B27: CUST0230 | C27: BR009 | D27: South | E27: Gold Loan | F27: Unsecured | G27: 13.03 | H27: 17.74 | I27: 0.2154 | J27: 0.2074 | K27: Overdue | L27: 706 | M27: Rejected | N27: =PROPER(M27) -> Rejected | O27: 09-01-2022 | P27: 09-01-2022 | R27: 180 | S27: 12.05
A28: TXN00027 | B28: CUST0332 | C28: BR005 | D28: West | E28: Auto Loan | F28: Semi-Secured | G28: 67.02 | H28: 15.51 | I28: 1.2623 | J28: 1.3125 | K28: Paid | L28: 855 | M28: Rejected | N28: =PROPER(M28) -> Rejected | O28: 07-09-2024 | P28: 07-09-2024 | R28: 84 | S28: 0
A29: TXN00028 | B29: CUST0283 | C29: BR002 | D29: East | E29: Home Loan | F29: Unsecured | G29: 62.13 | H29: 11.43 | I29: 0.6148 | J29: 1.6188 | L29: 740 | M29: APPROVED | N29: =PROPER(M29) -> Approved | O29: 31-03-2023 | P29: 31-03-2023 | Q29: 13-04-2023 | R29: 48 | S29: 55.63
A30: TXN00029 | B30: CUST0276 | C30: BR008 | D30: North | E30: Gold Loan | F30: Unsecured | G30: 20.25 | H30: 14.16 | I30: 0.3878 | J30: 0.3813 | K30: Partially Paid | L30: 891 | M30: Rejected | N30: =PROPER(M30) -> Rejected | O30: 25-05-2024 | P30: 25-05-2024 | R30: 84 | S30: 8.39
A31: TXN00030 | B31: CUST0180 | C31: BR005 | D31: West | E31: Gold Loan | F31: Secured | G31: 22.35 | H31: 15.66 | I31: 0.2511 | J31: 0.323 | K31: Overdue | L31: 639 | M31: Rejected | N31: =PROPER(M31) -> Rejected | O31: 18-05-2024 | P31: 18-05-2024 | R31: 180 | S31: 16.08
A32: TXN00031 | B32: CUST0307 | C32: BR002 | D32: South | E32: Personal Loan | F32: Unsecured | G32: 47.99 | H32: 18.35 | I32: 0.2875 | J32: 0.8756 | K32: Paid | L32: 830 | M32: Approved | N32: =PROPER(M32) -> Approved | O32: 18-04-2024 | P32: 18-04-2024 | Q32: 29-04-2024 | R32: 120 | S32: 0
A33: TXN00032 | B33: CUST0285 | C33: BR008 | D33: Central | E33: Personal Loan | F33: Secured | G33: 19.41 | H33: 13.59 | I33: 0.1093 | J33: 0.4475 | L33: 578 | M33: Under Review | N33: =PROPER(M33) -> Under Review | O33: 08-10-2024 | P33: 08-10-2024 | R33: 60 | S33: 11.17
A34: TXN00033 | B34: CUST0002 | C34: BR003 | D34: East | E34: Auto Loan | F34: Semi-Secured | G34: 83.59 | H34: 14.69 | I34: 1.5372 | J34: 1.3328 | K34: Pending | L34: 657 | M34: approved | N34: =PROPER(M34) -> Approved | O34: 17-05-2023 | P34: 17-05-2023 | Q34: 18-05-2023 | R34: 120 | S34: 16.84
A35: TXN00034 | B35: CUST0035 | C35: BR010 | D35: East | E35: Gold Loan | F35: Unsecured | G35: 56.99 | H35: 14.41 | I35: 0.6919 | J35: 2.7473 | K35: Overdue | L35: 573 | M35: APPROVED | N35: =PROPER(M35) -> Approved | O35: 05-02-2022 | P35: 05-02-2022 | Q35: 19-02-2022 | R35: 24 | S35: 18.27
A36: TXN00035 | B36: CUST0237 | C36: BR003 | D36: East | E36: Personal Loan | F36: Secured | G36: 27.99 | H36: 17.53 | I36: 0.2894 | J36: 0.7036 | K36: Overdue | L36: 841 | M36: APPROVED | N36: =PROPER(M36) -> Approved | O36: 07-06-2022 | P36: 07-06-2022 | Q36: 16-06-2022 | R36: 60 | S36: 7.41
A37: TXN00036 | B37: CUST0307 | C37: BR003 | D37: Central | E37: Auto Loan | F37: Unsecured | G37: 82.86 | H37: 10.81 | I37: 1.2662 | J37: 1.4105 | K37: Paid | L37: 830 | M37: APPROVED | N37: =PROPER(M37) -> Approved | O37: 22-12-2023 | P37: 22-12-2023 | Q37: 05-01-2024 | R37: 84 | S37: 0
A38: TXN00037 | B38: CUST0145 | C38: BR006 | D38: West | E38: Education Loan | F38: Unsecured | G38: 92.17 | H38: 9.9 | I38: 1.1568 | J38: 2.3332 | K38: Defaulted | L38: 704 | M38: APPROVED | N38: =PROPER(M38) -> Approved | O38: 12-12-2024 | P38: 12-12-2024 | Q38: 26-12-2024 | R38: 48 | S38: 50.9
A39: TXN00038 | B39: CUST0059 | C39: BR007 | D39: West | E39: Home Loan | F39: Secured | G39: 82.07 | H39: 12.77 | I39: 0.7939 | J39: 1.4828 | K39: Pending | L39: 702 | M39: approved | N39: =PROPER(M39) -> Approved | O39: 07-12-2024 | P39: 07-12-2024 | Q39: 20-12-2024 | R39: 84 | S39: 75.88
A40: TXN00039 | B40: CUST0382 | C40: BR002 | D40: South | E40: Personal Loan | F40: Semi-Secured | G40: 15.09 | H40: 8.88 | I40: 0.1049 | J40: 0.6886 | K40: Partially Paid | L40: 837 | M40: Rejected | N40: =PROPER(M40) -> Rejected | O40: 17-08-2022 | P40: 17-08-2022 | R40: 24 | S40: 2.51
...

Sheet Sheet28
A1: NPA_pct | B1: Region | C1: Payment_Status | D1: Transaction_ID
A2: 4.76 | B2: North | C2: Partially Paid | D2: TXN00001
A3: 2.73 | B3: North | C3: Partially Paid | D3: TXN00002
A4: 2.89 | B4: West | C4: Paid | D4: TXN00003
A5: 10.77 | B5: Central | C5: Paid | D5: TXN00004
A6: 10.85 | B6: East | C6: Defaulted | D6: TXN00005
A7: 8.83 | B7: Central | C7: Pending | D7: TXN00006
A8: 10.61 | B8: East | C8: Defaulted | D8: TXN00007
A9: 10.02 | B9: Central | C9: Paid | D9: TXN00008
A10: 6.85 | B10: South | C10: Partially Paid | D10: TXN00009
A11: 2.49 | B11: West | C11: Defaulted | D11: TXN00010
A12: 2.58 | B12: West | C12: Overdue | D12: TXN00011
A13: 11.55 | B13: North | C13: Pending | D13: TXN00012
... A16: 8.32 | B16: West | C16: Partially Paid | D16: TXN00015
A17: 9.32 | B17: North | D17: TXN00016
A18: 8.43 | B18: South | D18: TXN00017
A19: 4.74 | B19: West | C19: Defaulted | D19: TXN00018
A20: 4.8 | B20: North | C20: Paid | D20: TXN00019
A21: 7.15 | B21: Central | C21: Partially Paid | D21: TXN00020
A22: 4.7 | B22: West | C22: Pending | D22: TXN00021
A23: 2.96 | B23: South | C23: Overdue | D23: TXN00022
A24: 6.89 | B24: North | C24: Partially Paid | D24: TXN00023
A25: 6.38 | B25: South | C25: Overdue | D25: TXN00024
A26: 4.88 | B26: South | C26: Pending | D26: TXN00025
A27: 9.99 | B27: South | C27: Overdue | D27: TXN00026
A28: 11.62 | B28: West | C28: Paid | D28: TXN00027
A29: 7.69 | B29: East | D29: TXN00028
A30: 10.92 | B30: North | C30: Partially Paid | D30: TXN00029
A31: 8.03 | B31: West | C31: Overdue | D31: TXN00030
A32: 11.86 | B32: South | C32: Paid | D32: TXN00031
A33: 2.88 | B33: Central | D33: TXN00032
A34: 2.34 | B34: East | C34: Pending | D34: TXN00033
A35: 9.17 | B35: East | C35: Overdue | D35: TXN00034
A36: 10.24 | B36: East | C36: Overdue | D36: TXN00035
A37: 11.81 | B37: Central | C37: Paid | D37: TXN00036
B38: West | C38: Defaulted | D38: TXN00037
B39: West | C39: Pending | D39: TXN00038
B40: South | C40: Partially Paid | D40: TXN00039
B41: North | C41: Overdue | D41: TXN00040
B42: South | C42: Overdue | D42: TXN00041
...

Sheet Sheet14
A3: Region | B3: NPA%
A4: Central | B4: 0.1874063
A5: Central Total
A6: East | B6: 0.18790605
A7: East Total
A8: North | B8: 0.1954023
B9: 0.20789605
A10: North Total
A11: West | B11: 0.22088956
A12: West Total

Sheet Sheet18
A3: Region | B3: Sum of NPA% | C3: Count of Transaction_ID
A4: Central | B4: 0.1874063 | C4: 376
A5: East | B5: 0.18790605 | C5: 375
A6: North | B6: 0.40329835 | C6: 391
A7: South | C7: 416
A8: West | B8: 0.22088956 | C8: 442

Sheet Sheet10
A1: Transaction_ID | B1: Region | C1: Payment_Status | D1: NPA%
A2: TXN00001 | B2: North | C2: Partially Paid | D2: =COUNTIFS(C:C,"Defaulted")/COUNTA(A:A) -> 0.17941029
A3: TXN00002 | B3: North | C3: Partially Paid
A4: TXN00003 | B4: West | C4: Paid
A5: TXN00004 | B5: Central | C5: Paid
A6: TXN00005 | B6: East | C6: Defaulted
A7: TXN00006 | B7: Central | C7: Pending
A8: TXN00007 | B8: East | C8: Defaulted
A9: TXN00008 | B9: Central | C9: Paid
A10: TXN00009 | B10: South | C10: Partially Paid
A11: TXN00010 | B11: West | C11: Defaulted
A12: TXN00011 | B12: West | C12: Overdue
A13: TXN00012 | B13: North | C13: Pending
A14: TXN00013 | B14: East | C14: Partially Paid
... A16: TXN00015 | B16: West | C16: Partially Paid
A17: TXN00016 | B17: North
A18: TXN00017 | B18: South
A19: TXN00018 | B19: West | C19: Defaulted
A20: TXN00019 | B20: North | C20: Paid
A21: TXN00020 | B21: Central | C21: Partially Paid
A22: TXN00021 | B22: West | C22: Pending
A23: TXN00022 | B23: South | C23: Overdue
A24: TXN00023 | B24: North | C24: Partially Paid
A25: TXN00024 | B25: South | C25: Overdue
A26: TXN00025 | B26: South | C26: Pending
A27: TXN00026 | B27: South | C27: Overdue
A28: TXN00027 | B28: West | C28: Paid
A29: TXN00028 | B29: East
A30: TXN00029 | B30: North | C30: Partially Paid
A31: TXN00030 | B31: West | C31: Overdue
A32: TXN00031 | B32: South | C32: Paid
A33: TXN00032 | B33: Central
A34: TXN00033 | B34: East | C34: Pending
A35: TXN00034 | B35: East | C35: Overdue
A36: TXN00035 | B36: East | C36: Overdue
A37: TXN00036 | B37: Central | C37: Paid
A38: TXN00037 | B38: West | C38: Defaulted
A39: TXN00038 | B39: West | C39: Pending
A40: TXN00039 | B40: South | C40: Partially Paid
A41: TXN00040 | B41: North | C41: Overdue
...

Sheet Sheet8

Sheet Sheet1
A1: Column1 | B1: Column2 | C1: Column3 | D1: Column4

Sheet Sheet19
A3: Approval_Status | B3: Sum of Loan_Amount_Lakhs | C3: Sum of Outstanding_Balance
A4: approved | B4: 50873.35 | C4: 21573.06
A5: Rejected | B5: 15648.11 | C5: 6609.65
A6: Rejected | B6: 15786.06 | C6: 6871.7
A7: Under Review | B7: 18585.93 | C7: 8180.17

Sheet Sheet17

Sheet Sheet15

Sheet Sheet26
A3: Region | B3: Count of Actual_Revenue_Lakhs
A4: Central | B4: 6
A5: East | B5: 7
A6: North | B6: 7
A7: South | B7: 8
A8: West | B8: 8
A9: Grand Total | B9: 36

Sheet KPL_Summary
A1: KPI Summary — Monthly Finance Metrics
A3: Month | B3: Year | C3: Target_Revenue_Lakhs | D3: Actual_Revenue_Lakhs | E3: Loan_Approvals | F3: Loan_Rejections | G3: Recovery_Pct | H3: NPA_Pct | I3: New_Customers | J3: Avg_Loan_Amount | K3: Region | O3: Month | P3: Recovery_Pct
A4: Jan | B4: 2022 | C4: 515.82 | D4: 422.49 | E4: 130 | F4: 26 | G4: 82.9 | H4: 4.76 | I4: 82 | J4: 20.22 | K4: North | O4: Jan | P4: 82.9
A5: Feb | B5: 2022 | C5: 774.56 | D5: 701.67 | E5: 170 | F5: 53 | G5: 79.86 | H5: 2.73 | I5: 87 | J5: 28.94 | K5: North | O5: Feb | P5: 79.86
A6: Mar | B6: 2022 | C6: 751.88 | D6: 631.48 | E6: 144 | F6: 49 | G6: 91.39 | H6: 2.89 | I6: 60 | J6: 13.2 | K6: West | O6: Mar | P6: 91.39
A7: Apr | B7: 2022 | C7: 787.55 | D7: 929.2 | E7: 196 | F7: 59 | G7: 84.94 | H7: 10.77 | I7: 114 | J7: 29.68 | K7: Central | O7: Apr | P7: 84.94
A8: May | B8: 2022 | C8: 723.15 | D8: 718.94 | E8: 183 | F8: 56 | G8: 83.17 | H8: 10.85 | I8: 98 | J8: 15.93 | K8: East | O8: May | P8: 83.17
A9: Jun | B9: 2022 | C9: 500.13 | D9: 479.52 | E9: 148 | F9: 29 | G9: 82.52 | H9: 8.83 | I9: 35 | J9: 22.31 | K9: Central | O9: Jun | P9: 82.52
A10: Jul | B10: 2022 | C10: 640 | D10: 695.99 | E10: 94 | F10: 47 | G10: 77.96 | H10: 10.61 | I10: 107 | J10: 12.66 | K10: East | O10: Jul | P10: 77.96
A11: Aug | B11: 2022 | C11: 588.21 | D11: 627.42 | E11: 101 | F11: 57 | G11: 79.51 | H11: 10.02 | I11: 117 | J11: 28.4 | K11: Central | O11: Aug | P11: 79.51
A12: Sep | B12: 2022 | C12: 513.58 | D12: 484.94 | E12: 190 | F12: 43 | G12: 94.24 | H12: 6.85 | I12: 105 | J12: 16.44 | K12: South | O12: Sep | P12: 94.24
A13: Oct | B13: 2022 | C13: 573.64 | D13: 575.97 | E13: 187 | F13: 58 | G13: 95.39 | H13: 2.49 | I13: 30 | J13: 8.28 | K13: West | O13: Oct | P13: 95.39
A14: Nov | B14: 2022 | C14: 795.22 | D14: 888.69 | E14: 143 | F14: 24 | G14: 88.95 | H14: 2.58 | I14: 109 | J14: 12.82 | K14: West | O14: Nov | P14: 88.95
A15: Dec | B15: 2022 | C15: 688.12 | D15: 725.45 | E15: 96 | F15: 20 | G15: 79.32 | H15: 11.55 | I15: 88 | J15: 8.97 | K15: North | O15: Dec | P15: 79.32
... A39: Dec | B39: 2024 | C39: 567.36 | D39: 449.24 | E39: 98 | F39: 30 | G39: 90.87 | H39: 11.81 | I39: 120 | J39: 5.19 | K39: Central | O39: Dec | P39: 90.87
K40: West
K41: West
K42: South
K43: North
K44: South
K45: Central
K46: East
K47: North
K48: South
K49: North
K50: South
K51: West
... K2003: North

Sheet  (All Answers)
F1: Branches | G1: Processing Fees | H1: (4)Calculate total processing fees collected branch-wise. Which branch collected the highest fee? | I1: Credit_Score | J1: (9)Create a new column 'Risk_Category': If Credit_Score >= 750 → 'Low Risk', 650–749 → 'Medium Risk', < 650 → 'High Risk'. Use IFS or Nested IF. | L1: Target_Revenue_Lakhs | M1: Actual_Revenue_Lakhs | N1: (10)Create a column 'Target_Met': If Actual_Revenue >= Target_Revenue in KPI sheet → 'Yes', else 'No'. Use IF. | P1: Loan_Amount_Lakhs | Q1: (11)Flag transactions where Loan_Amount is blank (missing). Use IF + ISBLANK. | S1: Target_Revenue_Lakhs | T1: Actual_Revenue_Lakhs | U1: (12)In KPI sheet, create a column showing revenue difference (Actual - Target). Use IF to show 'Surplus' or 'Deficit' with the value. | W1: Branch_ID | X1: Manager | Y1: Transaction_ID | Z1: Branch_ID | AA1: (13)Use IFERROR with VLOOKUP to fetch Branch Manager name for each transaction. Handle missing Branch IDs gracefully. | AB1: Loan_Amount_Lakhs | AC1: Occupation | AD1: Annual Income From Customers Sheet | AE1: (5)Using SUMIFS, find total loan disbursed to 'Salaried' customers earning more than 10 Lakhs per year. (Requires VLOOKUP/XLOOKUP across Customers sheet) | AG1: Transaction_ID | AH1: (15)Extract the numeric part of Transaction_ID (e.g., TXN00001 → 00001). Use MID or RIGHT. | AI1: Gender | AJ1: (16)Standardize Gender column (convert M→Male, F→Female, lowercase → proper case). Use IF + UPPER/LOWER. | AK1: Customer Name | AL1: City | AM1: (17)Combine Customer Name and City as a single label: 'Amit Kumar | Bhubaneswar'. Use CONCAT or &. | AO1: Name | AP1: (18)Find all customers whose name starts with 'R'. Use LEFT + IF or FILTER. | AR1: Branch_Name | AS1: (19)Count the number of characters in each Branch Name. Use LEN. | AU1: Approval_Status | AV1: (20)Trim extra spaces from Approval_Status column and standardize to Proper Case. Use TRIM + PROPER. | AY1: Customer_ID | AZ1: City | BA1: Transaction_ID | BB1: Customer_ID in transition sheet | BC1: (27)For each Transaction, fetch the Customer's City using VLOOKUP (from Customers sheet). | BE1: Branch_ID | BF1: Target_Revenue_Lakhs | BG1: Transaction_ID | BH1: Branch_ID | BI1: (28)Fetch Branch Target Revenue for each transaction using XLOOKUP (from Branches sheet). | BK1: Customer_ID | BL1: (30)Build a lookup to check if a given Customer_ID exists in the Customers sheet. Use COUNTIF or XLOOKUP with IFERROR.
F2: BR001 | G2: =SUMIFS(Transitions!I:I,Transitions!C:C,"BR001") -> 122.964 | H2: =VLOOKUP(LARGE(G2:G11,1),CHOOSE({1,2},G2:G11,F2:F11),2,FALSE) -> BR003 | I2: 557 | J2: {=_xlfn.IFS(I2>=750,"Low Risk",AND(I2>=650,I2<=749),"Medium Risk",I2<650,"High Risk")} -> High Risk | L2: 515.82 | M2: 422.49 | N2: =IF(M2>=L2,"Yes","No") -> No | P2: 73.8 | Q2: =IF(ISBLANK(P2),"missing","Available") -> Available | S2: 515.82 | T2: 422.49 | U2: {=_xlfn.IFS(T2>S2,"Surplus",T2<S2,"Deficit")} -> Deficit | W2: BR001 | X2: Rajesh Kumar | Y2: TXN00001 | Z2: BR008 | AA2: =VLOOKUP(Z2,$W$2:$X$11,2,FALSE) -> Kavita Rath | AB2: 73.8 | AC2: retired | AD2: 43.5 | AE2: =SUMIFS(AB:AB,AC:AC,"Salaried",AD:AD,">10") -> 2945.36 | AG2: TXN00001 | AH2: =RIGHT(AG2,5) -> 00001 | AI2: Male | AJ2: =IF(UPPER(AI2)="M","Male","Female") -> Female | AK2: Mira Pradhan | AL2: Dhenkanal | AM2: =_xlfn.CONCAT(AK2,"|",AL2) -> Mira Pradhan|Dhenkanal | AO2: Mira Pradhan | AP2: =IF(LEFT(AO2,1)="R",AO2,"Not True") -> Not True | AR2: Bhubaneswar Main | AS2: =LEN(AR2) -> 16 | AU2: approved | AV2: =PROPER(TRIM(AU2)) -> Approved | AY2: CUST0001 | AZ2: Dhenkanal | BA2: TXN00001 | BB2: CUST0184 | BC2: =VLOOKUP(BB2,$AY$2:$AZ$501,2,FALSE) -> Jharsuguda | BE2: BR001 | BF2: 209.86 | BG2: TXN00001 | BH2: BR008 | BI2: =VLOOKUP(BH2,$BE$2:$BF$11,2,FALSE) -> 103.83 | BK2: CUST0001 | BL2: =IF(COUNTIF(BK:BK,BK2)>0,"Exists","Does Not Exists") -> Exists | BM2: 32 | BN2: Sum of Loan_Amount_Lakhs | BO2: Product | BV2: 34 ---- | BW2: Year | BX2: 2024
A3: SECTION A — AGGREGATE & CONDITIONAL FUNCTIONS | F3: BR002 | G3: =SUMIFS(Transitions!I:I,Transitions!C:C,"BR002") -> 125.9619 | I3: 600 | J3: {=_xlfn.IFS(I3>=750,"Low Risk",AND(I3>=650,I3<=749),"Medium Risk",I3<650,"High Risk")} -> High Risk | L3: 774.56 | M3: 701.67 | N3: =IF(M3>=L3,"Yes","No") -> No | P3: 6.55 | Q3: =IF(ISBLANK(P3),"missing","Available") -> Available | S3: 774.56 | T3: 701.67 | U3: {=_xlfn.IFS(T3>S3,"Surplus",T3<S3,"Deficit")} -> Deficit | W3: BR002 | X3: Priya Mohanty | Y3: TXN00002 | Z3: BR008 | AA3: =VLOOKUP(Z3,$W$2:$X$11,2,FALSE) -> Kavita Rath | AB3: 6.55 | AC3: Government Employee | AD3: 20.15 | AG3: TXN00002 | AH3: =RIGHT(AG3,5) -> 00002 | AI3: Male | AJ3: =IF(UPPER(AI3)="M","Male","Female") -> Female | AK3: Sita Rath | AL3: Balasore | AM3: =_xlfn.CONCAT(AK3,"|",AL3) -> Sita Rath|Balasore | AO3: Sita Rath | AP3: =IF(LEFT(AO3,1)="R",AO3,"Not True") -> Not True | AR3: Cuttack Central | AS3: =LEN(AR3) -> 15 | AU3: Rejected | AV3: =PROPER(TRIM(AU3)) -> Rejected | AY3: CUST0002 | AZ3: Balasore | BA3: TXN00002 | BB3: CUST0428 | BC3: =VLOOKUP(BB3,$AY$2:$AZ$501,2,FALSE) -> Bhubaneswar | BE3: BR002 | BF3: 105.8 | BG3: TXN00002 | BH3: BR008 | BI3: =VLOOKUP(BH3,$BE$2:$BF$11,2,FALSE) -> 103.83 | BK3: CUST0002 | BL3: =IF(COUNTIF(BK:BK,BK3)>0,"Exists","Does Not Exists") -> Exists | BN3: Region | BO3: Auto Loan | BP3: Business Loan | BQ3: Education Loan | BR3: Gold Loan | BS3: Home Loan | BT3: Personal Loan | BU3: Grand Total
A4: Q1 | B4: Calculate the total Loan Amount (in Lakhs) for all APPROVED transactions in the 'East' region. Use SUMIFS. | C4: =SUMIFS(Transitions!G:G,Transitions!N:N,"Approved",Transitions!D:D,"East") -> 10719.63 | D4: (Lakhs) | F4: BR003 | G4: =SUMIFS(Transitions!I:I,Transitions!C:C,"BR003") -> 146.9439 | I4: 690 | J4: {=_xlfn.IFS(I4>=750,"Low Risk",AND(I4>=650,I4<=749),"Medium Risk",I4<650,"High Risk")} -> Medium Risk | L4: 751.88 | M4: 631.48 | N4: =IF(M4>=L4,"Yes","No") -> No | P4: 47.65 | Q4: =IF(ISBLANK(P4),"missing","Available") -> Available | S4: 751.88 | T4: 631.48 | U4: {=_xlfn.IFS(T4>S4,"Surplus",T4<S4,"Deficit")} -> Deficit | W4: BR003 | X4: Suresh Panda | Y4: TXN00003 | Z4: BR003 | AA4: =VLOOKUP(Z4,$W$2:$X$11,2,FALSE) -> Suresh Panda | AB4: 47.65 | AC4: Government Employee | AD4: 49.51 | AG4: TXN00003 | AH4: =RIGHT(AG4,5) -> 00003 | AI4: female | AJ4: =IF(UPPER(AI4)="M","Male","Female") -> Female | AK4: Kavita Rout | AL4: Sambalpur | AM4: =_xlfn.CONCAT(AK4,"|",AL4) -> Kavita Rout|Sambalpur | AO4: Kavita Rout | AP4: =IF(LEFT(AO4,1)="R",AO4,"Not True") -> Not True | AR4: Rourkela Industrial | AS4: =LEN(AR4) -> 19 | AU4: Rejected | AV4: =PROPER(TRIM(AU4)) -> Rejected | AY4: CUST0003 | AZ4: Sambalpur | BA4: TXN00003 | BB4: CUST0377 | BC4: =VLOOKUP(BB4,$AY$2:$AZ$501,2,FALSE) -> Jharsuguda | BE4: BR003 | BF4: 197.62 | BG4: TXN00003 | BH4: BR003 | BI4: =VLOOKUP(BH4,$BE$2:$BF$11,2,FALSE) -> 197.62 | BK4: CUST0003 | BL4: =IF(COUNTIF(BK:BK,BK4)>0,"Exists","Does Not Exists") -> Exists | BN4: Central | BO4: 2751.61 | BP4: 4153.45 | BQ4: 3001.45 | BR4: 3565.22 | BS4: 2929.92 | BT4: 2710 | BU4: 19111.65 | BW4: Month | BX4: Sum of Target_Revenue_Lakhs | BY4: Sum of Actual_Revenue_Lakhs
A5: Q2 | B5: Count how many transactions have Payment_Status = 'Overdue'. Use COUNTIF. | C5: =COUNTIF(Transitions!K:K,"Overdue") -> 393 | F5: BR004 | G5: =SUMIFS(Transitions!I:I,Transitions!C:C,"BR003") -> 146.9439 | I5: 797 | J5: {=_xlfn.IFS(I5>=750,"Low Risk",AND(I5>=650,I5<=749),"Medium Risk",I5<650,"High Risk")} -> Low Risk | L5: 787.55 | M5: 929.2 | N5: =IF(M5>=L5,"Yes","No") -> Yes | P5: 7.33 | Q5: =IF(ISBLANK(P5),"missing","Available") -> Available | S5: 787.55 | T5: 929.2 | U5: {=_xlfn.IFS(T5>S5,"Surplus",T5<S5,"Deficit")} -> Surplus | W5: BR004 | X5: Anita Das | Y5: TXN00004 | Z5: BR008 | AA5: =VLOOKUP(Z5,$W$2:$X$11,2,FALSE) -> Kavita Rath | AB5: 7.33 | AC5: Salaried | AD5: 47.32 | AG5: TXN00004 | AH5: =RIGHT(AG5,5) -> 00004 | AI5: M | AJ5: =IF(UPPER(AI5)="M","Male","Female") -> Male | AK5: Ashok Mohanty | AL5: Balasore | AM5: =_xlfn.CONCAT(AK5,"|",AL5) -> Ashok Mohanty|Balasore | AO5: Ashok Mohanty | AP5: =IF(LEFT(AO5,1)="R",AO5,"Not True") -> Not True | AR5: Puri Tourism | AS5: =LEN(AR5) -> 12 | AU5: Rejected | AV5: =PROPER(TRIM(AU5)) -> Rejected | AY5: CUST0004 | AZ5: Balasore | BA5: TXN00004 | BB5: CUST0050 | BC5: =VLOOKUP(BB5,$AY$2:$AZ$501,2,FALSE) -> Rourkela | BE5: BR004 | BF5: 104.66 | BG5: TXN00004 | BH5: BR008 | BI5: =VLOOKUP(BH5,$BE$2:$BF$11,2,FALSE) -> 103.83 | BK5: CUST0004 | BL5: =IF(COUNTIF(BK:BK,BK5)>0,"Exists","Does Not Exists") -> Exists | BN5: East | BO5: 2948.59 | BP5: 3211.64 | BQ5: 3388.14 | BR5: 3182.5 | BS5: 3324.26 | BT5: 3706.32 | BU5: 19761.45 | BW5: Jan | BX5: 778.81 | BY5: 702.41
A6: Q3 | B6: Find the average EMI for Home Loan customers with Credit Score above 700. Use AVERAGEIFS. | C6: =AVERAGEIFS(Transitions!J:J,Transitions!E:E,"Home Loan",Transitions!L:L,">700") -> 1.5571347 | D6: (Lakhs) | F6: BR005 | G6: =SUMIFS(Transitions!I:I,Transitions!C:C,"BR005") -> 126.066 | I6: 751 | J6: {=_xlfn.IFS(I6>=750,"Low Risk",AND(I6>=650,I6<=749),"Medium Risk",I6<650,"High Risk")} -> Low Risk | L6: 723.15 | M6: 718.94 | N6: =IF(M6>=L6,"Yes","No") -> No | P6: 58.02 | Q6: =IF(ISBLANK(P6),"missing","Available") -> Available | S6: 723.15 | T6: 718.94 | U6: {=_xlfn.IFS(T6>S6,"Surplus",T6<S6,"Deficit")} -> Deficit | W6: BR005 | X6: Bikash Nayak | Y6: TXN00005 | Z6: BR007 | AA6: =VLOOKUP(Z6,$W$2:$X$11,2,FALSE) -> Ramesh Behera | AB6: 58.02 | AC6: retired | AD6: 15.35 | AG6: TXN00005 | AH6: =RIGHT(AG6,5) -> 00005 | AI6: M | AJ6: =IF(UPPER(AI6)="M","Male","Female") -> Male | AK6: Arjun Nayak | AL6: Rourkela | AM6: =_xlfn.CONCAT(AK6,"|",AL6) -> Arjun Nayak|Rourkela | AO6: Arjun Nayak | AP6: =IF(LEFT(AO6,1)="R",AO6,"Not True") -> Not True | AR6: Sambalpur Regional | AS6: =LEN(AR6) -> 18 | AU6: Rejected | AV6: =PROPER(TRIM(AU6)) -> Rejected | AY6: CUST0005 | AZ6: Rourkela | BA6: TXN00005 | BB6: CUST0378 | BC6: =VLOOKUP(BB6,$AY$2:$AZ$501,2,FALSE) -> Bhubaneswar | BE6: BR005 | BF6: 190.31 | BG6: TXN00005 | BH6: BR007 | BI6: =VLOOKUP(BH6,$BE$2:$BF$11,2,FALSE) -> 224.53 | BK6: CUST0005 | BL6: =IF(COUNTIF(BK:BK,BK6)>0,"Exists","Does Not Exists") -> Exists | BN6: North | BO6: 2649.88 | BP6: 2782.17 | BQ6: 3002.91 | BR6: 3571.26 | BS6: 3396.06 | BT6: 4226.59 | BU6: 19628.87 | BW6: Feb | BX6: 555.85 | BY6: 523.94
A7: Q4 | B7: Calculate total processing fees collected branch-wise. Which branch collected the highest fee? | C7: Branches | D7: Processing Fees | F7: BR006 | G7: =SUMIFS(Transitions!I:I,Transitions!C:C,"BR006") -> 127.3054 | I7: 748 | J7: {=_xlfn.IFS(I7>=750,"Low Risk",AND(I7>=650,I7<=749),"Medium Risk",I7<650,"High Risk")} -> Medium Risk | L7: 500.13 | M7: 479.52 | N7: =IF(M7>=L7,"Yes","No") -> No | P7: 25.12 | Q7: =IF(ISBLANK(P7),"missing","Available") -> Available | S7: 500.13 | T7: 479.52 | U7: {=_xlfn.IFS(T7>S7,"Surplus",T7<S7,"Deficit")} -> Deficit | W7: BR006 | X7: Sunita Sahu | Y7: TXN00006 | Z7: BR006 | AA7: =VLOOKUP(Z7,$W$2:$X$11,2,FALSE) -> Sunita Sahu | AB7: 25.12 | AC7: retired | AD7: 34.98 | AG7: TXN00006 | AH7: =RIGHT(AG7,5) -> 00006 | AI7: Male | AJ7: =IF(UPPER(AI7)="M","Male","Female") -> Female | AK7: Nisha Das | AL7: Cuttack | AM7: =_xlfn.CONCAT(AK7,"|",AL7) -> Nisha Das|Cuttack | AO7: Nisha Das | AP7: =IF(LEFT(AO7,1)="R",AO7,"Not True") -> Not True | AR7: Berhampur South | AS7: =LEN(AR7) -> 15 | AU7: approved | AV7: =PROPER(TRIM(AU7)) -> Approved | AY7: CUST0006 | AZ7: Cuttack | BA7: TXN00006 | BB7: CUST0087 | BC7: =VLOOKUP(BB7,$AY$2:$AZ$501,2,FALSE) -> Bhubaneswar | BE7: BR006 | BF7: 162.3 | BG7: TXN00006 | BH7: BR006 | BI7: =VLOOKUP(BH7,$BE$2:$BF$11,2,FALSE) -> 162.3 | BK7: CUST0006 | BL7: =IF(COUNTIF(BK:BK,BK7)>0,"Exists","Does Not Exists") -> Exists | BN7: South | BO7: 3615.17 | BP7: 3141.53 | BQ7: 3667.88 | BR7: 4382.45 | BS7: 3335.53 | BT7: 3511.95 | BU7: 21654.51 | BW7: Mar | BX7: 451.01 | BY7: 392.3
C8: BR007 | D8: =SUMIFS(Transitions!I:I,Transitions!C:C,' (All Answers)'!C8) -> 128.2743 | F8: BR007 | G8: =SUMIFS(Transitions!I:I,Transitions!C:C,"BR007") -> 128.2743 | I8: 866 | J8: {=_xlfn.IFS(I8>=750,"Low Risk",AND(I8>=650,I8<=749),"Medium Risk",I8<650,"High Risk")} -> Low Risk | L8: 640 | M8: 695.99 | N8: =IF(M8>=L8,"Yes","No") -> Yes | W8: BR007 | X8: Ramesh Behera | Y8: TXN00007 | Z8: BR010 | AA8: =VLOOKUP(Z8,$W$2:$X$11,2,FALSE) -> Pooja Tripathi | AB8: 80.93 | AC8: retired | AD8: 38.29 | AG8: TXN00007 | AH8: =RIGHT(AG8,5) -> 00007 | AI8: female | AJ8: =IF(UPPER(AI8)="M","Male","Female") -> Female | AK8: Seema Kumar | AL8: Cuttack | AM8: =_xlfn.CONCAT(AK8,"|",AL8) -> Seema Kumar|Cuttack | AO8: Seema Kumar | AP8: =IF(LEFT(AO8,1)="R",AO8,"Not True") -> Not True | AR8: Balasore North | AS8: =LEN(AR8) -> 14 | AU8: approved | AV8: =PROPER(TRIM(AU8)) -> Approved | AY8: CUST0007 | AZ8: Cuttack | BA8: TXN00007 | BB8: CUST0334 | BC8: =VLOOKUP(BB8,$AY$2:$AZ$501,2,FALSE) -> Puri | BE8: BR007 | BF8: 224.53 | BG8: TXN00007 | BH8: BR010 | BI8: =VLOOKUP(BH8,$BE$2:$BF$11,2,FALSE) -> 251.78 | BK8: CUST0007 | BL8: =IF(COUNTIF(BK:BK,BK8)>0,"Exists","Does Not Exists") -> Exists | BN8: West | BO8: 3698.96 | BP8: 3903.88 | BQ8: 2834.7 | BR8: 3270.67 | BS8: 3858.58 | BT8: 3170.18 | BU8: 20736.97 | BW8: Apr | BX8: 656.67 | BY8: 553.88
A9: Q5 | B9: Using SUMIFS, find total loan disbursed to 'Salaried' customers earning more than 10 Lakhs per year. (Requires VLOOKUP/XLOOKUP across Customers sheet) | C9: Done | F9: BR008 | G9: =SUMIFS(Transitions!I:I,Transitions!C:C,"BR008") -> 131.6551 | I9: 887 | J9: {=_xlfn.IFS(I9>=750,"Low Risk",AND(I9>=650,I9<=749),"Medium Risk",I9<650,"High Risk")} -> Low Risk | L9: 588.21 | M9: 627.42 | N9: =IF(M9>=L9,"Yes","No") -> Yes | P9: 80.93 | Q9: =IF(ISBLANK(P9),"missing","Available") -> Available | S9: 640 | T9: 695.99 | U9: {=_xlfn.IFS(T9>S9,"Surplus",T9<S9,"Deficit")} -> Surplus | W9: BR008 | X9: Kavita Rath | Y9: TXN00008 | Z9: BR008 | AA9: =VLOOKUP(Z9,$W$2:$X$11,2,FALSE) -> Kavita Rath | AB9: 82.82 | AC9: Salaried | AD9: 17.03 | AG9: TXN00008 | AH9: =RIGHT(AG9,5) -> 00008 | AI9: male | AJ9: =IF(UPPER(AI9)="M","Male","Female") -> Female | AK9: Amit Mishra | AL9: Rourkela | AM9: =_xlfn.CONCAT(AK9,"|",AL9) -> Amit Mishra|Rourkela | AO9: Amit Mishra | AP9: =IF(LEFT(AO9,1)="R",AO9,"Not True") -> Not True | AR9: Angul Mining | AS9: =LEN(AR9) -> 12 | AU9: approved | AV9: =PROPER(TRIM(AU9)) -> Approved | AY9: CUST0008 | AZ9: Rourkela | BA9: TXN00008 | BB9: CUST0093 | BC9: =VLOOKUP(BB9,$AY$2:$AZ$501,2,FALSE) -> Angul | BE9: BR008 | BF9: 103.83 | BG9: TXN00008 | BH9: BR008 | BI9: =VLOOKUP(BH9,$BE$2:$BF$11,2,FALSE) -> 103.83 | BK9: CUST0008 | BL9: =IF(COUNTIF(BK:BK,BK9)>0,"Exists","Does Not Exists") -> Exists | BW9: May | BX9: 647.49 | BY9: 701.48
A10: Q6 | B10: Find the count of loans where Amount > 50 Lakhs AND Approval_Status = 'Approved'. Use COUNTIFS. | C10: =COUNTIFS(Transitions!G:G,">50",Transitions!M:M,"approved") -> 524 | F10: BR009 | G10: =SUMIFS(Transitions!I:I,Transitions!C:C,"BR009") -> 127.8823 | I10: 793 | J10: {=_xlfn.IFS(I10>=750,"Low Risk",AND(I10>=650,I10<=749),"Medium Risk",I10<650,"High Risk")} -> Low Risk | L10: 513.58 | M10: 484.94 | N10: =IF(M10>=L10,"Yes","No") -> No | P10: 82.82 | Q10: =IF(ISBLANK(P10),"missing","Available") -> Available | S10: 588.21 | T10: 627.42 | U10: {=_xlfn.IFS(T10>S10,"Surplus",T10<S10,"Deficit")} -> Surplus | W10: BR009 | X10: Deepak Mishra | Y10: TXN00009 | Z10: BR009 | AA10: =VLOOKUP(Z10,$W$2:$X$11,2,FALSE) -> Deepak Mishra | AB10: 66.27 | AC10: Government Employee | AG10: TXN00009 | AH10: =RIGHT(AG10,5) -> 00009 | AI10: Male | AJ10: =IF(UPPER(AI10)="M","Male","Female") -> Female | AK10: Prakash Swain | AL10: Jharsuguda | AM10: =_xlfn.CONCAT(AK10,"|",AL10) -> Prakash Swain|Jharsuguda | AO10: Prakash Swain | AP10: =IF(LEFT(AO10,1)="R",AO10,"Not True") -> Not True | AR10: Jharsuguda Energy | AS10: =LEN(AR10) -> 17 | AU10: Rejected | AV10: =PROPER(TRIM(AU10)) -> Rejected | AY10: CUST0009 | AZ10: Jharsuguda | BA10: TXN00009 | BB10: CUST0277 | BC10: =VLOOKUP(BB10,$AY$2:$AZ$501,2,FALSE) -> Dhenkanal | BE10: BR009 | BF10: 144.98 | BG10: TXN00009 | BH10: BR009 | BI10: =VLOOKUP(BH10,$BE$2:$BF$11,2,FALSE) -> 144.98 | BK10: CUST0009 | BL10: =IF(COUNTIF(BK:BK,BK10)>0,"Exists","Does Not Exists") -> Exists | BM10: 33 | BN10: Month | BO10: Sum of Loan_Approvals | BP10: Sum of Loan_Rejections | BW10: Jun | BX10: 486.09 | BY10: 558.06
A11: Q7 | B11: Find the MAX and MIN loan amount for each loan product type. | C11: Loan product type | D11: Maximum | E11: Minimum | F11: BR010 | G11: =SUMIFS(Transitions!I:I,Transitions!C:C,"BR010") -> 115.1412 | I11: 713 | J11: {=_xlfn.IFS(I11>=750,"Low Risk",AND(I11>=650,I11<=749),"Medium Risk",I11<650,"High Risk")} -> Medium Risk | L11: 573.64 | M11: 575.97 | N11: =IF(M11>=L11,"Yes","No") -> Yes | P11: 66.27 | Q11: =IF(ISBLANK(P11),"missing","Available") -> Available | S11: 513.58 | T11: 484.94 | U11: {=_xlfn.IFS(T11>S11,"Surplus",T11<S11,"Deficit")} -> Deficit | W11: BR010 | X11: Pooja Tripathi | Y11: TXN00010 | Z11: BR004 | AA11: =VLOOKUP(Z11,$W$2:$X$11,2,FALSE) -> Anita Das | AB11: 62.07 | AC11: Self-Employed | AD11: 47.5 | AG11: TXN00010 | AH11: =RIGHT(AG11,5) -> 00010 | AI11: Male | AJ11: =IF(UPPER(AI11)="M","Male","Female") -> Female | AK11: Ravi Dash | AL11: Dhenkanal | AM11: =_xlfn.CONCAT(AK11,"|",AL11) -> Ravi Dash|Dhenkanal | AO11: Ravi Dash | AP11: =IF(LEFT(AO11,1)="R",AO11,"Not True") -> Ravi Dash | AR11: Dhenkanal Rural | AS11: =LEN(AR11) -> 15 | AU11: Rejected | AV11: =PROPER(TRIM(AU11)) -> Rejected | AY11: CUST0010 | AZ11: Dhenkanal | BA11: TXN00010 | BB11: CUST0146 | BC11: =VLOOKUP(BB11,$AY$2:$AZ$501,2,FALSE) -> Angul | BE11: BR010 | BF11: 251.78 | BG11: TXN00010 | BH11: BR004 | BI11: =VLOOKUP(BH11,$BE$2:$BF$11,2,FALSE) -> 104.66 | BK11: CUST0010 | BL11: =IF(COUNTIF(BK:BK,BK11)>0,"Exists","Does Not Exists") -> Exists | BN11: Jan | BO11: 439 | BP11: 124 | BW11: Jul | BX11: 488.42 | BY11: 568.29
C12: Business Loan | D12: =_xlfn.MAXIFS(Transitions!G:G,Transitions!E:E,C12) -> 99.91 | E12: =_xlfn.MINIFS(Transitions!G:G,Transitions!E:E,C12) -> 1.04 | I12: 639 | J12: {=_xlfn.IFS(I12>=750,"Low Risk",AND(I12>=650,I12<=749),"Medium Risk",I12<650,"High Risk")} -> High Risk | L12: 795.22 | M12: 888.69 | N12: =IF(M12>=L12,"Yes","No") -> Yes | P12: 62.07 | Q12: =IF(ISBLANK(P12),"missing","Available") -> Available | S12: 573.64 | T12: 575.97 | U12: {=_xlfn.IFS(T12>S12,"Surplus",T12<S12,"Deficit")} -> Surplus | Y12: TXN00011 | Z12: BR004 | AA12: =VLOOKUP(Z12,$W$2:$X$11,2,FALSE) -> Anita Das | AB12: 33.27 | AC12: retired | AD12: 23.59 | AG12: TXN00011 | AH12: =RIGHT(AG12,5) -> 00011 | AI12: female | AJ12: =IF(UPPER(AI12)="M","Male","Female") -> Female | AK12: Prakash Behera | AL12: Berhampur | AM12: =_xlfn.CONCAT(AK12,"|",AL12) -> Prakash Behera|Berhampur | AO12: Prakash Behera | AP12: =IF(LEFT(AO12,1)="R",AO12,"Not True") -> Not True | AU12: Rejected | AV12: =PROPER(TRIM(AU12)) -> Rejected | AY12: CUST0011 | AZ12: Berhampur | BA12: TXN00011 | BB12: CUST0459 | BC12: =VLOOKUP(BB12,$AY$2:$AZ$501,2,FALSE) -> Sambalpur | BG12: TXN00011 | BH12: BR004 | BI12: =VLOOKUP(BH12,$BE$2:$BF$11,2,FALSE) -> 104.66 | BK12: CUST0011 | BL12: =IF(COUNTIF(BK:BK,BK12)>0,"Exists","Does Not Exists") -> Exists | BN12: Feb | BO12: 394 | BP12: 127 | BW12: Aug | BX12: 626.94 | BY12: 692.38
A13: Q8 | B13: What is the total Outstanding Balance for all 'Defaulted' loans? | C13: =SUMIFS(Transitions!S:S,Transitions!K:K,"Defaulted") -> 9564.88 | I13: 731 | J13: {=_xlfn.IFS(I13>=750,"Low Risk",AND(I13>=650,I13<=749),"Medium Risk",I13<650,"High Risk")} -> Medium Risk | L13: 688.12 | M13: 725.45 | N13: =IF(M13>=L13,"Yes","No") -> Yes | P13: 33.27 | Q13: =IF(ISBLANK(P13),"missing","Available") -> Available | S13: 795.22 | T13: 888.69 | U13: {=_xlfn.IFS(T13>S13,"Surplus",T13<S13,"Deficit")} -> Surplus | Y13: TXN00012 | Z13: BR004 | AA13: =VLOOKUP(Z13,$W$2:$X$11,2,FALSE) -> Anita Das | AB13: 48.96 | AC13: Salaried | AD13: 32.66 | AG13: TXN00012 | AH13: =RIGHT(AG13,5) -> 00012 | AI13: Female | AJ13: =IF(UPPER(AI13)="M","Male","Female") -> Female | AK13: Vijay Rout | AL13: Jharsuguda | AM13: =_xlfn.CONCAT(AK13,"|",AL13) -> Vijay Rout|Jharsuguda | AO13: Vijay Rout | AP13: =IF(LEFT(AO13,1)="R",AO13,"Not True") -> Not True | AU13: approved | AV13: =PROPER(TRIM(AU13)) -> Approved | AY13: CUST0012 | AZ13: Jharsuguda | BA13: TXN00012 | BB13: CUST0457 | BC13: =VLOOKUP(BB13,$AY$2:$AZ$501,2,FALSE) -> Bhubaneswar | BG13: TXN00012 | BH13: BR004 | BI13: =VLOOKUP(BH13,$BE$2:$BF$11,2,FALSE) -> 104.66 | BK13: CUST0012 | BL13: =IF(COUNTIF(BK:BK,BK13)>0,"Exists","Does Not Exists") -> Exists | BN13: Mar | BO13: 406 | BP13: 119 | BW13: Sep | BX13: 433.71 | BY13: 469.59
A14: SECTION B — LOGICAL FUNCTIONS | I14: 738 | J14: {=_xlfn.IFS(I14>=750,"Low Risk",AND(I14>=650,I14<=749),"Medium Risk",I14<650,"High Risk")} -> Medium Risk | L14: 766.04 | M14: 617.34 | N14: =IF(M14>=L14,"Yes","No") -> No | P14: 48.96 | Q14: =IF(ISBLANK(P14),"missing","Available") -> Available | S14: 688.12 | T14: 725.45 | U14: {=_xlfn.IFS(T14>S14,"Surplus",T14<S14,"Deficit")} -> Surplus | Y14: TXN00013 | Z14: BR004 | AA14: =VLOOKUP(Z14,$W$2:$X$11,2,FALSE) -> Anita Das | AB14: 69.53 | AC14: retired | AD14: 29.84 | AG14: TXN00013 | AH14: =RIGHT(AG14,5) -> 00013 | AI14: Female | AJ14: =IF(UPPER(AI14)="M","Male","Female") -> Female | AK14: Bikash Dash | AL14: Dhenkanal | AM14: =_xlfn.CONCAT(AK14,"|",AL14) -> Bikash Dash|Dhenkanal | AO14: Bikash Dash | AP14: =IF(LEFT(AO14,1)="R",AO14,"Not True") -> Not True | AU14: Rejected | AV14: =PROPER(TRIM(AU14)) -> Rejected | AY14: CUST0013 | AZ14: Dhenkanal | BA14: TXN00013 | BB14: CUST0139 | BC14: =VLOOKUP(BB14,$AY$2:$AZ$501,2,FALSE) -> Rourkela | BG14: TXN00013 | BH14: BR004 | BI14: =VLOOKUP(BH14,$BE$2:$BF$11,2,FALSE) -> 104.66 | BK14: CUST0013 | BL14: =IF(COUNTIF(BK:BK,BK14)>0,"Exists","Does Not Exists") -> Exists | BN14: Apr | BO14: 454 | BP14: 122 | BW14: Oct | BX14: 661.38 | BY14: 696.33
A15: Q9 | B15: Create a new column 'Risk_Category': If Credit_Score >= 750 → 'Low Risk', 650–749 → 'Medium Risk', < 650 → 'High Risk'. Use IFS or Nested IF. | C15: Done | I15: 863 | J15: {=_xlfn.IFS(I15>=750,"Low Risk",AND(I15>=650,I15<=749),"Medium Risk",I15<650,"High Risk")} -> Low Risk | L15: 540.74 | M15: 599.37 | N15: =IF(M15>=L15,"Yes","No") -> Yes | P15: 69.53 | Q15: =IF(ISBLANK(P15),"missing","Available") -> Available | S15: 766.04 | T15: 617.34 | U15: {=_xlfn.IFS(T15>S15,"Surplus",T15<S15,"Deficit")} -> Deficit | Y15: TXN00014 | Z15: BR010 | AA15: =VLOOKUP(Z15,$W$2:$X$11,2,FALSE) -> Pooja Tripathi | AB15: 85.65 | AC15: Government Employee | AD15: 5.55 | AG15: TXN00014 | AH15: =RIGHT(AG15,5) -> 00014 | AI15: M | AJ15: =IF(UPPER(AI15)="M","Male","Female") -> Male | AK15: Rekha Patnaik | AL15: Balasore | AM15: =_xlfn.CONCAT(AK15,"|",AL15) -> Rekha Patnaik|Balasore | AO15: Rekha Patnaik | AP15: =IF(LEFT(AO15,1)="R",AO15,"Not True") -> Rekha Patnaik | AU15: approved | AV15: =PROPER(TRIM(AU15)) -> Approved | AY15: CUST0014 | AZ15: Balasore | BA15: TXN00014 | BB15: CUST0407 | BC15: =VLOOKUP(BB15,$AY$2:$AZ$501,2,FALSE) -> Dhenkanal | BG15: TXN00014 | BH15: BR010 | BI15: =VLOOKUP(BH15,$BE$2:$BF$11,2,FALSE) -> 251.78 | BK15: CUST0014 | BL15: =IF(COUNTIF(BK:BK,BK15)>0,"Exists","Does Not Exists") -> Exists | BN15: May | BO15: 456 | BP15: 117 | BW15: Nov | BX15: 500.47 | BY15: 423.91
A16: Q10 | B16: Create a column 'Target_Met': If Actual_Revenue >= Target_Revenue in KPI sheet → 'Yes', else 'No'. Use IF. | C16: Done | I16: 560 | J16: {=_xlfn.IFS(I16>=750,"Low Risk",AND(I16>=650,I16<=749),"Medium Risk",I16<650,"High Risk")} -> High Risk | L16: 460.2 | M16: 364.59 | N16: =IF(M16>=L16,"Yes","No") -> No | P16: 85.65 | Q16: =IF(ISBLANK(P16),"missing","Available") -> Available | S16: 540.74 | T16: 599.37 | U16: {=_xlfn.IFS(T16>S16,"Surplus",T16<S16,"Deficit")} -> Surplus | Y16: TXN00015 | Z16: BR006 | AA16: =VLOOKUP(Z16,$W$2:$X$11,2,FALSE) -> Sunita Sahu | AB16: 89.29 | AC16: Self-Employed | AD16: 16.09 | AG16: TXN00015 | AH16: =RIGHT(AG16,5) -> 00015 | AI16: Female | AJ16: =IF(UPPER(AI16)="M","Male","Female") -> Female | AK16: Anita Behera | AL16: Dhenkanal | AM16: =_xlfn.CONCAT(AK16,"|",AL16) -> Anita Behera|Dhenkanal | AO16: Anita Behera | AP16: =IF(LEFT(AO16,1)="R",AO16,"Not True") -> Not True | AU16: approved | AV16: =PROPER(TRIM(AU16)) -> Approved | AY16: CUST0015 | AZ16: Dhenkanal | BA16: TXN00015 | BB16: CUST0127 | BC16: =VLOOKUP(BB16,$AY$2:$AZ$501,2,FALSE) -> Puri | BG16: TXN00015 | BH16: BR006 | BI16: =VLOOKUP(BH16,$BE$2:$BF$11,2,FALSE) -> 162.3 | BK16: CUST0015 | BL16: =IF(COUNTIF(BK:BK,BK16)>0,"Exists","Does Not Exists") -> Exists | BN16: Jun | BO16: 487 | BP16: 91 | BW16: Dec | BX16: 567.36 | BY16: 449.24
A17: Q11 | B17: Flag transactions where Loan_Amount is blank (missing). Use IF + ISBLANK. | C17: Done | I17: 582 | J17: {=_xlfn.IFS(I17>=750,"Low Risk",AND(I17>=650,I17<=749),"Medium Risk",I17<650,"High Risk")} -> High Risk | L17: 794.16 | M17: 721.7 | N17: =IF(M17>=L17,"Yes","No") -> No | P17: 89.29 | Q17: =IF(ISBLANK(P17),"missing","Available") -> Available | S17: 460.2 | T17: 364.59 | U17: {=_xlfn.IFS(T17>S17,"Surplus",T17<S17,"Deficit")} -> Deficit | Y17: TXN00016 | Z17: BR008 | AA17: =VLOOKUP(Z17,$W$2:$X$11,2,FALSE) -> Kavita Rath | AB17: 24.81 | AC17: Self-Employed | AD17: 25.62 | AG17: TXN00016 | AH17: =RIGHT(AG17,5) -> 00016 | AI17: Male | AJ17: =IF(UPPER(AI17)="M","Male","Female") -> Female | AK17: Manoj Rout | AL17: Cuttack | AM17: =_xlfn.CONCAT(AK17,"|",AL17) -> Manoj Rout|Cuttack | AO17: Manoj Rout | AP17: =IF(LEFT(AO17,1)="R",AO17,"Not True") -> Not True | AU17: Under Review | AV17: =PROPER(TRIM(AU17)) -> Under Review | AY17: CUST0016 | AZ17: Cuttack | BA17: TXN00016 | BB17: CUST0202 | BC17: =VLOOKUP(BB17,$AY$2:$AZ$501,2,FALSE) -> Bhubaneswar | BG17: TXN00016 | BH17: BR008 | BI17: =VLOOKUP(BH17,$BE$2:$BF$11,2,FALSE) -> 103.83 | BK17: CUST0016 | BL17: =IF(COUNTIF(BK:BK,BK17)>0,"Exists","Does Not Exists") -> Exists | BN17: Jul | BO17: 366 | BP17: 147
A18: Q12 | B18: In KPI sheet, create a column showing revenue difference (Actual - Target). Use IF to show 'Surplus' or 'Deficit' with the value. | C18: Done | I18: 649 | J18: {=_xlfn.IFS(I18>=750,"Low Risk",AND(I18>=650,I18<=749),"Medium Risk",I18<650,"High Risk")} -> High Risk | L18: 496.23 | M18: 492.41 | N18: =IF(M18>=L18,"Yes","No") -> No | P18: 24.81 | Q18: =IF(ISBLANK(P18),"missing","Available") -> Available | S18: 794.16 | T18: 721.7 | U18: {=_xlfn.IFS(T18>S18,"Surplus",T18<S18,"Deficit")} -> Deficit | Y18: TXN00017 | Z18: BR005 | AA18: =VLOOKUP(Z18,$W$2:$X$11,2,FALSE) -> Bikash Nayak | AB18: 85.93 | AC18: retired | AD18: 10.28 | AG18: TXN00017 | AH18: =RIGHT(AG18,5) -> 00017 | AI18: M | AJ18: =IF(UPPER(AI18)="M","Male","Female") -> Male | AK18: Mira Sethi | AL18: Balasore | AM18: =_xlfn.CONCAT(AK18,"|",AL18) -> Mira Sethi|Balasore | AO18: Mira Sethi | AP18: =IF(LEFT(AO18,1)="R",AO18,"Not True") -> Not True | AU18: Rejected | AV18: =PROPER(TRIM(AU18)) -> Rejected | AY18: CUST0017 | AZ18: Balasore | BA18: TXN00017 | BB18: CUST0343 | BC18: =VLOOKUP(BB18,$AY$2:$AZ$501,2,FALSE) -> Balasore | BG18: TXN00017 | BH18: BR005 | BI18: =VLOOKUP(BH18,$BE$2:$BF$11,2,FALSE) -> 190.31 | BK18: CUST0017 | BL18: =IF(COUNTIF(BK:BK,BK18)>0,"Exists","Does Not Exists") -> Exists | BN18: Aug | BO18: 411 | BP18: 141 | BU18: 36 | BV18: Month | BW18: Average of Recovery_Pct
